<?xml version="1.0" ?>
<!-- =================================================================================== -->
<!-- |    This document was autogenerated by xacro from xacro/solo12.urdf.xacro        | -->
<!-- |    EDITING THIS FILE BY HAND IS NOT RECOMMENDED                                 | -->
<!-- =================================================================================== -->
<robot name="solo" xmlns:controller="http://playerstage.sourceforge.net/gazebo/xmlschema/#controller" xmlns:interface="http://playerstage.sourceforge.net/gazebo/xmlschema/#interface" xmlns:sensor="http://playerstage.sourceforge.net/gazebo/xmlschema/#sensor" xmlns:xacro="http://playerstage.sourceforge.net/gazebo/xmlschema/#interface">
  <!-- Floating-base Joint -->
  <link name="world"/>
  <joint name="floating_base_joint" type="floating">
    <origin rpy="0 0 0" xyz="0 0 0"/>
    <parent link="world"/>
    <child link="base_link"/>
  </joint>
  <joint name="floating_base" type="fixed">
    <origin rpy="0 0 0" xyz="0 0 0"/>
    <parent link="base_link"/>
    <child link="trunk"/>
  </joint>
  <link name="trunk"/>
  <!-- Fixed joint to add dummy inertia link -->
  <joint name="base_to_base_inertia" type="fixed">
    <parent link="trunk"/>
    <child link="base_inertia"/>
    <origin rpy="0 0 0" xyz="0 0 0"/>
  </joint>
  <!-- Dummy inertia link, because KDL cannot have inertia on the base link -->
  <link name="base_inertia">
    <inertial>
      <origin rpy="0 0 0" xyz="0 0 0"/>
      <mass value="1.63315091"/>
      <!-- The base is extremely symmetrical. -->
      <inertia ixx="0.00578574" ixy="0.0" ixz="0.0" iyy="0.01938108" iyz="0.0" izz="0.02476124"/>
    </inertial>
  </link>
  <!-- This file is based on: https://atlas.is.localnet/confluence/display/AMDW/Quadruped+URDF+Files -->
  <link name="base_link">
    <!-- BASE LINK VISUAL -->
    <visual>
      <origin rpy="0 0 0" xyz="0 0 0"/>
      <geometry>
        <mesh filename="package://solo_description/meshes/stl/with_foot/solo_body.stl"/>
      </geometry>
      <material name="grey">
        <color rgba="0.8 0.8 0.8 1.0"/>
      </material>
    </visual>
    <!-- BASE LINK COLLISION -->
    <collision>
      <origin rpy="0 0 0" xyz="0 0 0"/>
      <geometry>
        <mesh filename="package://solo_description/meshes/stl/with_foot/solo_body.stl"/>
      </geometry>
      <material name="grey">
        <color rgba="0.8 0.8 0.8 1.0"/>
      </material>
    </collision>
    <!-- Bullet specific paramters -->
    <contact>
      <lateral_friction value="1.0"/>
      <restitution value="0.5"/>
    </contact>
  </link>
  <!-- END BASE LINK -->
  <joint name="FL_haa_joint" type="revolute">
    <parent link="trunk"/>
    <child link="FL_hip_assembly"/>
    <limit effort="1000" lower="-10" upper="10" velocity="1000"/>
    <!-- joints rotates around the x-axis -->
    <axis xyz="1 0 0"/>
    <origin rpy="0 0 0" xyz="0.19 0.1046 0"/>
    <!-- pybullet simulation parameters -->
    <dynamics damping="0.0" friction="0.0"/>
  </joint>
  <link name="FL_hip_assembly">
    <!-- create a dummy hip_assembly link to join the two joints -->
    <inertial>
      <origin rpy="0 0 0" xyz="0. 0. 0."/>
      <!-- Adding extra weight for actuator module at hip_assembly. -->
      <mass value="0.150"/>
      <inertia ixx="0.00000001" ixy="0.0" ixz="0.0" iyy="0.00000001" iyz="0" izz="0.00000001"/>
    </inertial>
  </link>
  <joint name="FL_hfe_joint" type="revolute">
    <parent link="FL_hip_assembly"/>
    <child link="FL_upper_leg"/>
    <limit effort="1000" lower="-10" upper="10" velocity="1000"/>
    <!-- joints rotates around the y-axis -->
    <axis xyz="0 1 0"/>
    <!-- placement of the joint -->
    <origin rpy="0 0 0" xyz="0 0 0"/>
    <!-- pybullet simulation parameters -->
    <dynamics damping="0.0" friction="0.0"/>
  </joint>
  <!-- UPPER LEG LINK -->
  <link name="FL_upper_leg">
    <!-- Left upper leg inertia -->
    <inertial>
      <origin rpy="0 0 0" xyz="0.00001377 0.01935853 -0.07870700"/>
      <mass value="0.14853845"/>
      <inertia ixx="0.00041107" ixy="0.0" ixz="0.0" iyy="0.00041193" iyz="0.00004671" izz="0.00003024"/>
    </inertial>
    <!-- UPPER LEG LINK VISUAL -->
    <visual>
      <origin rpy="0 0 0" xyz="0 0 0"/>
      <geometry>
        <mesh filename="package://solo_description/meshes/stl/with_foot/solo_upper_leg_left_side.stl"/>
      </geometry>
      <material name="grey">
        <color rgba="0.8 0.8 0.8 1.0"/>
      </material>
    </visual>
    <!-- UPPER LEG LINK COLLISION -->
    <collision>
      <origin rpy="0 0 0" xyz="0 0 0"/>
      <geometry>
        <mesh filename="package://solo_description/meshes/stl/with_foot/solo_upper_leg_left_side.stl"/>
      </geometry>
      <material name="grey">
        <color rgba="0.8 0.8 0.8 1.0"/>
      </material>
    </collision>
    <!-- Bullet specific paramters -->
    <contact>
      <lateral_friction value="1.0"/>
      <restitution value="0.5"/>
    </contact>
  </link>
  <!-- END UPPER LEG LINK -->
  <!-- KFE JOINT -->
  <joint name="FL_kfe_joint" type="revolute">
    <parent link="FL_upper_leg"/>
    <child link="FL_lower_leg"/>
    <limit effort="1000" lower="-10" upper="10" velocity="1000"/>
    <!-- joints rotates around the y-axis -->
    <axis xyz="0 1 0"/>
    <origin rpy="0 0 0" xyz="0 0.03745 -0.16"/>
    <!-- pybullet simulation parameters -->
    <dynamics damping="0.0" friction="0.0"/>
  </joint>
  <!-- LOWERLEG -->
  <link name="FL_lower_leg">
    <!-- Left lower leg inertia -->
    <inertial>
      <origin rpy="0 0 0" xyz="0.0 0.00787644 -0.08928215"/>
      <mass value="0.03070001"/>
      <inertia ixx="0.00012024" ixy="0.0" ixz="0.0" iyy="0.00012029" iyz="0.00000305" izz="0.00000216"/>
    </inertial>
    <!-- LOWER LEG LINK VISUAL -->
    <visual>
      <origin rpy="0 0 0" xyz="0 0 0"/>
      <geometry>
        <mesh filename="package://solo_description/meshes/stl/with_foot/solo_lower_leg_left_side.stl"/>
      </geometry>
      <material name="grey">
        <color rgba="0.8 0.8 0.8 1.0"/>
      </material>
    </visual>
    <!-- LOWER LEG LINK COLLISION -->
    <collision>
      <origin rpy="0 0 0" xyz="0 0 0"/>
      <geometry>
        <mesh filename="package://solo_description/meshes/stl/with_foot/solo_lower_leg_left_side.stl"/>
      </geometry>
      <material name="grey">
        <color rgba="0.8 0.8 0.8 1.0"/>
      </material>
    </collision>
    <!-- Bullet specific paramters -->
    <contact>
      <lateral_friction value="1.0"/>
      <restitution value="0.5"/>
    </contact>
  </link>
  <!-- END LOWER LEG LINK -->
  <!-- KFE: Joint between the upper leg and the lower leg -->
  <joint name="FL_ankle" type="fixed">
    <parent link="FL_lower_leg"/>
    <child link="FL_foot"/>
    <!-- Joint placement -->
    <origin rpy="0 0 0" xyz="0 0 -0.16"/>
    <!-- Limits (usefull?) -->
    <limit effort="1000" lower="-10" upper="10" velocity="1000"/>
    <!-- pybullet simulation parameters -->
    <dynamics damping="0.0" friction="0.0"/>
  </joint>
  <!-- FOOT -->
  <link name="FL_foot">
    <!-- FOOT INERTIAL -->
    <!-- This link is symmetrical left or right -->
    <inertial>
      <origin rpy="0 0 0" xyz="0 0 0.00035767"/>
      <mass value="0.00693606"/>
      <inertia ixx="0.00000057" ixy="0.0" ixz="0.0" iyy="0.00000084" iyz="0.0" izz="0.00000053"/>
    </inertial>
    <!-- FOOT VISUAL -->
    <visual>
      <origin rpy="0 0 0" xyz="0 0 0"/>
      <geometry>
        <mesh filename="package://solo_description/meshes/stl/with_foot/solo_foot.stl"/>
      </geometry>
      <material name="grey">
        <color rgba="0.8 0.8 0.8 1.0"/>
      </material>
    </visual>
    <!-- FOOT COLLISION -->
    <collision>
      <origin rpy="0 0 0" xyz="0 0 0"/>
      <geometry>
        <mesh filename="package://solo_description/meshes/stl/with_foot/solo_foot.stl"/>
      </geometry>
      <material name="grey">
        <color rgba="0.8 0.8 0.8 1.0"/>
      </material>
    </collision>
    <!-- Bullet specific paramters -->
    <contact>
      <lateral_friction value="1.0"/>
      <restitution value="0.5"/>
    </contact>
  </link>
  <!-- END LOWER LEG LINK -->
  <!-- Hip assembly -->
  <transmission name="FL_haa_trans">
    <type>transmission_interface/SimpleTransmission</type>
    <joint name="FL_haa_joint">
      <hardwareInterface>EffortJointInterface</hardwareInterface>
    </joint>
    <actuator name="FL_haa_motor">
      <hardwareInterface>EffortJointInterface</hardwareInterface>
      <mechanicalReduction>1</mechanicalReduction>
    </actuator>
  </transmission>
  <!-- Upper leg -->
  <transmission name="FL_hfe_trans">
    <type>transmission_interface/SimpleTransmission</type>
    <joint name="FL_hfe_joint">
      <hardwareInterface>EffortJointInterface</hardwareInterface>
    </joint>
    <actuator name="FL_hfe_motor">
      <hardwareInterface>EffortJointInterface</hardwareInterface>
      <mechanicalReduction>1</mechanicalReduction>
    </actuator>
  </transmission>
  <!-- Lower leg -->
  <transmission name="FL_kfe_trans">
    <type>transmission_interface/SimpleTransmission</type>
    <joint name="FL_kfe_joint">
      <hardwareInterface>EffortJointInterface</hardwareInterface>
    </joint>
    <actuator name="FL_kfe_motor">
      <hardwareInterface>EffortJointInterface</hardwareInterface>
      <mechanicalReduction>1</mechanicalReduction>
    </actuator>
  </transmission>
  <gazebo reference="FL_haa_joint">
    <provideFeedback>true</provideFeedback>
  </gazebo>
  <gazebo reference="FL_kfe_joint">
    <provideFeedback>true</provideFeedback>
  </gazebo>
  <gazebo reference="FL_hfe_joint">
    <provideFeedback>true</provideFeedback>
  </gazebo>
  <gazebo reference="FL_upperleg">
    <kp>1000000.0</kp>
    <kd>100.0</kd>
    <mu1>1.5</mu1>
    <mu2>1.5</mu2>
    <fdir1>1 0 0</fdir1>
    <maxVel>1.0</maxVel>
    <minDepth>0.00</minDepth>
  </gazebo>
  <gazebo reference="FL_lowerleg">
    <kp>1000000.0</kp>
    <kd>100.0</kd>
    <mu1>1.0</mu1>
    <mu2>1.0</mu2>
    <maxVel>1.0</maxVel>
    <maxContacts>1</maxContacts>
    <sensor name="FL_shin_contact_sensor" type="contact">
      <always_on>true</always_on>
      <update_rate>250.0</update_rate>
      <contact>
        <collision>FL_lowerleg_collision</collision>
      </contact>
      <!-- the sensor readings in terms of force torques are expressed in the lowerleg frame
                because gazebo lumps the fake footframe with the real parent link, the normals are in the world frame-->
      <plugin filename="libgazebo_ros_bumper.so" name="FL_shin_bumper">
        <bumperTopicName>/solo/FL_shin_bumper</bumperTopicName>
      </plugin>
    </sensor>
  </gazebo>
  <gazebo reference="FL_foot">
    <kp>1000000.0</kp>
    <kd>100.0</kd>
    <mu1>1.0</mu1>
    <mu2>1.0</mu2>
    <maxVel>1.0</maxVel>
    <maxContacts>1</maxContacts>
    <sensor name="FL_foot_contact_sensor" type="contact">
      <always_on>true</always_on>
      <update_rate>250.0</update_rate>
      <contact>
        <collision>FL_lowerleg_fixed_joint_lump__FL_foot_collision_1</collision>
      </contact>
      <!-- the sensor readings in terms of force torques are expressed in the lowerleg frame
                                because gazebo lumps the fake footframe with the real parent link, the normals are in the world frame-->
      <plugin filename="libgazebo_ros_bumper.so" name="FL_foot_bumper">
        <bumperTopicName>/solo/FL_foot_bumper</bumperTopicName>
        <robotNamespace>solo</robotNamespace>
      </plugin>
    </sensor>
    <material>Gazebo/Black</material>
  </gazebo>
  <joint name="FR_haa_joint" type="revolute">
    <parent link="trunk"/>
    <child link="FR_hip_assembly"/>
    <limit effort="1000" lower="-10" upper="10" velocity="1000"/>
    <!-- joints rotates around the x-axis -->
    <axis xyz="1 0 0"/>
    <origin rpy="0 0 0" xyz="0.19 -0.1046 0"/>
    <!-- pybullet simulation parameters -->
    <dynamics damping="0.0" friction="0.0"/>
  </joint>
  <link name="FR_hip_assembly">
    <!-- create a dummy hip_assembly link to join the two joints -->
    <inertial>
      <origin rpy="0 0 0" xyz="0. 0. 0."/>
      <!-- Adding extra weight for actuator module at hip_assembly. -->
      <mass value="0.150"/>
      <inertia ixx="0.00000001" ixy="0.0" ixz="0.0" iyy="0.00000001" iyz="0" izz="0.00000001"/>
    </inertial>
  </link>
  <joint name="FR_hfe_joint" type="revolute">
    <parent link="FR_hip_assembly"/>
    <child link="FR_upper_leg"/>
    <limit effort="1000" lower="-10" upper="10" velocity="1000"/>
    <!-- joints rotates around the y-axis -->
    <axis xyz="0 1 0"/>
    <!-- placement of the joint -->
    <origin rpy="0 0 0" xyz="0 0 0"/>
    <!-- pybullet simulation parameters -->
    <dynamics damping="0.0" friction="0.0"/>
  </joint>
  <!-- UPPER LEG LINK -->
  <link name="FR_upper_leg">
    <!-- Right upper leg inertia -->
    <inertial>
      <origin rpy="0 0 0" xyz="-0.00001377 -0.01935853 -0.07870700"/>
      <mass value="0.14853845"/>
      <inertia ixx="0.00041107" ixy="0.0" ixz="0.0" iyy="0.00041193" iyz="-0.00004671" izz="0.00003024"/>
    </inertial>
    <!-- UPPER LEG LINK VISUAL -->
    <visual>
      <origin rpy="0 0 0" xyz="0 0 0"/>
      <geometry>
        <mesh filename="package://solo_description/meshes/stl/with_foot/solo_upper_leg_right_side.stl"/>
      </geometry>
      <material name="grey">
        <color rgba="0.8 0.8 0.8 1.0"/>
      </material>
    </visual>
    <!-- UPPER LEG LINK COLLISION -->
    <collision>
      <origin rpy="0 0 0" xyz="0 0 0"/>
      <geometry>
        <mesh filename="package://solo_description/meshes/stl/with_foot/solo_upper_leg_right_side.stl"/>
      </geometry>
      <material name="grey">
        <color rgba="0.8 0.8 0.8 1.0"/>
      </material>
    </collision>
    <!-- Bullet specific paramters -->
    <contact>
      <lateral_friction value="1.0"/>
      <restitution value="0.5"/>
    </contact>
  </link>
  <!-- END UPPER LEG LINK -->
  <!-- KFE JOINT -->
  <joint name="FR_kfe_joint" type="revolute">
    <parent link="FR_upper_leg"/>
    <child link="FR_lower_leg"/>
    <limit effort="1000" lower="-10" upper="10" velocity="1000"/>
    <!-- joints rotates around the y-axis -->
    <axis xyz="0 1 0"/>
    <origin rpy="0 0 0" xyz="0 -0.03745 -0.16"/>
    <!-- pybullet simulation parameters -->
    <dynamics damping="0.0" friction="0.0"/>
  </joint>
  <!-- LOWERLEG -->
  <link name="FR_lower_leg">
    <!-- Right lower leg inertia -->
    <inertial>
      <origin rpy="0 0 0" xyz="0.0 0.00787644 -0.08928215"/>
      <mass value="0.03070001"/>
      <inertia ixx="0.00012024" ixy="0.0" ixz="0.0" iyy="0.00012029" iyz="-0.00000305" izz="0.00000216"/>
    </inertial>
    <!-- LOWER LEG LINK VISUAL -->
    <visual>
      <origin rpy="0 0 0" xyz="0 0 0"/>
      <geometry>
        <mesh filename="package://solo_description/meshes/stl/with_foot/solo_lower_leg_right_side.stl"/>
      </geometry>
      <material name="grey">
        <color rgba="0.8 0.8 0.8 1.0"/>
      </material>
    </visual>
    <!-- LOWER LEG LINK COLLISION -->
    <collision>
      <origin rpy="0 0 0" xyz="0 0 0"/>
      <geometry>
        <mesh filename="package://solo_description/meshes/stl/with_foot/solo_lower_leg_right_side.stl"/>
      </geometry>
      <material name="grey">
        <color rgba="0.8 0.8 0.8 1.0"/>
      </material>
    </collision>
    <!-- Bullet specific paramters -->
    <contact>
      <lateral_friction value="1.0"/>
      <restitution value="0.5"/>
    </contact>
  </link>
  <!-- END LOWER LEG LINK -->
  <!-- KFE: Joint between the upper leg and the lower leg -->
  <joint name="FR_ankle" type="fixed">
    <parent link="FR_lower_leg"/>
    <child link="FR_foot"/>
    <!-- Joint placement -->
    <origin rpy="0 0 0" xyz="0 0 -0.16"/>
    <!-- Limits (usefull?) -->
    <limit effort="1000" lower="-10" upper="10" velocity="1000"/>
    <!-- pybullet simulation parameters -->
    <dynamics damping="0.0" friction="0.0"/>
  </joint>
  <!-- FOOT -->
  <link name="FR_foot">
    <!-- FOOT INERTIAL -->
    <!-- This link is symmetrical left or right -->
    <inertial>
      <origin rpy="0 0 0" xyz="0 0 0.00035767"/>
      <mass value="0.00693606"/>
      <inertia ixx="0.00000057" ixy="0.0" ixz="0.0" iyy="0.00000084" iyz="0.0" izz="0.00000053"/>
    </inertial>
    <!-- FOOT VISUAL -->
    <visual>
      <origin rpy="0 0 0" xyz="0 0 0"/>
      <geometry>
        <mesh filename="package://solo_description/meshes/stl/with_foot/solo_foot.stl"/>
      </geometry>
      <material name="grey">
        <color rgba="0.8 0.8 0.8 1.0"/>
      </material>
    </visual>
    <!-- FOOT COLLISION -->
    <collision>
      <origin rpy="0 0 0" xyz="0 0 0"/>
      <geometry>
        <mesh filename="package://solo_description/meshes/stl/with_foot/solo_foot.stl"/>
      </geometry>
      <material name="grey">
        <color rgba="0.8 0.8 0.8 1.0"/>
      </material>
    </collision>
    <!-- Bullet specific paramters -->
    <contact>
      <lateral_friction value="1.0"/>
      <restitution value="0.5"/>
    </contact>
  </link>
  <!-- END LOWER LEG LINK -->
  <!-- Hip assembly -->
  <transmission name="FR_haa_trans">
    <type>transmission_interface/SimpleTransmission</type>
    <joint name="FR_haa_joint">
      <hardwareInterface>EffortJointInterface</hardwareInterface>
    </joint>
    <actuator name="FR_haa_motor">
      <hardwareInterface>EffortJointInterface</hardwareInterface>
      <mechanicalReduction>1</mechanicalReduction>
    </actuator>
  </transmission>
  <!-- Upper leg -->
  <transmission name="FR_hfe_trans">
    <type>transmission_interface/SimpleTransmission</type>
    <joint name="FR_hfe_joint">
      <hardwareInterface>EffortJointInterface</hardwareInterface>
    </joint>
    <actuator name="FR_hfe_motor">
      <hardwareInterface>EffortJointInterface</hardwareInterface>
      <mechanicalReduction>1</mechanicalReduction>
    </actuator>
  </transmission>
  <!-- Lower leg -->
  <transmission name="FR_kfe_trans">
    <type>transmission_interface/SimpleTransmission</type>
    <joint name="FR_kfe_joint">
      <hardwareInterface>EffortJointInterface</hardwareInterface>
    </joint>
    <actuator name="FR_kfe_motor">
      <hardwareInterface>EffortJointInterface</hardwareInterface>
      <mechanicalReduction>1</mechanicalReduction>
    </actuator>
  </transmission>
  <gazebo reference="FR_haa_joint">
    <provideFeedback>true</provideFeedback>
  </gazebo>
  <gazebo reference="FR_kfe_joint">
    <provideFeedback>true</provideFeedback>
  </gazebo>
  <gazebo reference="FR_hfe_joint">
    <provideFeedback>true</provideFeedback>
  </gazebo>
  <gazebo reference="FR_upperleg">
    <kp>1000000.0</kp>
    <kd>100.0</kd>
    <mu1>1.5</mu1>
    <mu2>1.5</mu2>
    <fdir1>1 0 0</fdir1>
    <maxVel>1.0</maxVel>
    <minDepth>0.00</minDepth>
  </gazebo>
  <gazebo reference="FR_lowerleg">
    <kp>1000000.0</kp>
    <kd>100.0</kd>
    <mu1>1.0</mu1>
    <mu2>1.0</mu2>
    <maxVel>1.0</maxVel>
    <maxContacts>1</maxContacts>
    <sensor name="FR_shin_contact_sensor" type="contact">
      <always_on>true</always_on>
      <update_rate>250.0</update_rate>
      <contact>
        <collision>FR_lowerleg_collision</collision>
      </contact>
      <!-- the sensor readings in terms of force torques are expressed in the lowerleg frame
                because gazebo lumps the fake footframe with the real parent link, the normals are in the world frame-->
      <plugin filename="libgazebo_ros_bumper.so" name="FR_shin_bumper">
        <bumperTopicName>/solo/FR_shin_bumper</bumperTopicName>
      </plugin>
    </sensor>
  </gazebo>
  <gazebo reference="FR_foot">
    <kp>1000000.0</kp>
    <kd>100.0</kd>
    <mu1>1.0</mu1>
    <mu2>1.0</mu2>
    <maxVel>1.0</maxVel>
    <maxContacts>1</maxContacts>
    <sensor name="FR_foot_contact_sensor" type="contact">
      <always_on>true</always_on>
      <update_rate>250.0</update_rate>
      <contact>
        <collision>FR_lowerleg_fixed_joint_lump__FR_foot_collision_1</collision>
      </contact>
      <!-- the sensor readings in terms of force torques are expressed in the lowerleg frame
                                because gazebo lumps the fake footframe with the real parent link, the normals are in the world frame-->
      <plugin filename="libgazebo_ros_bumper.so" name="FR_foot_bumper">
        <bumperTopicName>/solo/FR_foot_bumper</bumperTopicName>
        <robotNamespace>solo</robotNamespace>
      </plugin>
    </sensor>
    <material>Gazebo/Black</material>
  </gazebo>
  <joint name="HL_haa_joint" type="revolute">
    <parent link="trunk"/>
    <child link="HL_hip_assembly"/>
    <limit effort="1000" lower="-10" upper="10" velocity="1000"/>
    <!-- joints rotates around the x-axis -->
    <axis xyz="1 0 0"/>
    <origin rpy="0 0 0" xyz="-0.19 0.1046 0"/>
    <!-- pybullet simulation parameters -->
    <dynamics damping="0.0" friction="0.0"/>
  </joint>
  <link name="HL_hip_assembly">
    <!-- create a dummy hip_assembly link to join the two joints -->
    <inertial>
      <origin rpy="0 0 0" xyz="0. 0. 0."/>
      <!-- Adding extra weight for actuator module at hip_assembly. -->
      <mass value="0.150"/>
      <inertia ixx="0.00000001" ixy="0.0" ixz="0.0" iyy="0.00000001" iyz="0" izz="0.00000001"/>
    </inertial>
  </link>
  <joint name="HL_hfe_joint" type="revolute">
    <parent link="HL_hip_assembly"/>
    <child link="HL_upper_leg"/>
    <limit effort="1000" lower="-10" upper="10" velocity="1000"/>
    <!-- joints rotates around the y-axis -->
    <axis xyz="0 1 0"/>
    <!-- placement of the joint -->
    <origin rpy="0 0 0" xyz="0 0 0"/>
    <!-- pybullet simulation parameters -->
    <dynamics damping="0.0" friction="0.0"/>
  </joint>
  <!-- UPPER LEG LINK -->
  <link name="HL_upper_leg">
    <!-- Left upper leg inertia -->
    <inertial>
      <origin rpy="0 0 0" xyz="0.00001377 0.01935853 -0.07870700"/>
      <mass value="0.14853845"/>
      <inertia ixx="0.00041107" ixy="0.0" ixz="0.0" iyy="0.00041193" iyz="0.00004671" izz="0.00003024"/>
    </inertial>
    <!-- UPPER LEG LINK VISUAL -->
    <visual>
      <origin rpy="0 0 0" xyz="0 0 0"/>
      <geometry>
        <mesh filename="package://solo_description/meshes/stl/with_foot/solo_upper_leg_left_side.stl"/>
      </geometry>
      <material name="grey">
        <color rgba="0.8 0.8 0.8 1.0"/>
      </material>
    </visual>
    <!-- UPPER LEG LINK COLLISION -->
    <collision>
      <origin rpy="0 0 0" xyz="0 0 0"/>
      <geometry>
        <mesh filename="package://solo_description/meshes/stl/with_foot/solo_upper_leg_left_side.stl"/>
      </geometry>
      <material name="grey">
        <color rgba="0.8 0.8 0.8 1.0"/>
      </material>
    </collision>
    <!-- Bullet specific paramters -->
    <contact>
      <lateral_friction value="1.0"/>
      <restitution value="0.5"/>
    </contact>
  </link>
  <!-- END UPPER LEG LINK -->
  <!-- KFE JOINT -->
  <joint name="HL_kfe_joint" type="revolute">
    <parent link="HL_upper_leg"/>
    <child link="HL_lower_leg"/>
    <limit effort="1000" lower="-10" upper="10" velocity="1000"/>
    <!-- joints rotates around the y-axis -->
    <axis xyz="0 1 0"/>
    <origin rpy="0 0 0" xyz="0 0.03745 -0.16"/>
    <!-- pybullet simulation parameters -->
    <dynamics damping="0.0" friction="0.0"/>
  </joint>
  <!-- LOWERLEG -->
  <link name="HL_lower_leg">
    <!-- Left lower leg inertia -->
    <inertial>
      <origin rpy="0 0 0" xyz="0.0 0.00787644 -0.08928215"/>
      <mass value="0.03070001"/>
      <inertia ixx="0.00012024" ixy="0.0" ixz="0.0" iyy="0.00012029" iyz="0.00000305" izz="0.00000216"/>
    </inertial>
    <!-- LOWER LEG LINK VISUAL -->
    <visual>
      <origin rpy="0 0 0" xyz="0 0 0"/>
      <geometry>
        <mesh filename="package://solo_description/meshes/stl/with_foot/solo_lower_leg_left_side.stl"/>
      </geometry>
      <material name="grey">
        <color rgba="0.8 0.8 0.8 1.0"/>
      </material>
    </visual>
    <!-- LOWER LEG LINK COLLISION -->
    <collision>
      <origin rpy="0 0 0" xyz="0 0 0"/>
      <geometry>
        <mesh filename="package://solo_description/meshes/stl/with_foot/solo_lower_leg_left_side.stl"/>
      </geometry>
      <material name="grey">
        <color rgba="0.8 0.8 0.8 1.0"/>
      </material>
    </collision>
    <!-- Bullet specific paramters -->
    <contact>
      <lateral_friction value="1.0"/>
      <restitution value="0.5"/>
    </contact>
  </link>
  <!-- END LOWER LEG LINK -->
  <!-- KFE: Joint between the upper leg and the lower leg -->
  <joint name="HL_ankle" type="fixed">
    <parent link="HL_lower_leg"/>
    <child link="HL_foot"/>
    <!-- Joint placement -->
    <origin rpy="0 0 0" xyz="0 0 -0.16"/>
    <!-- Limits (usefull?) -->
    <limit effort="1000" lower="-10" upper="10" velocity="1000"/>
    <!-- pybullet simulation parameters -->
    <dynamics damping="0.0" friction="0.0"/>
  </joint>
  <!-- FOOT -->
  <link name="HL_foot">
    <!-- FOOT INERTIAL -->
    <!-- This link is symmetrical left or right -->
    <inertial>
      <origin rpy="0 0 0" xyz="0 0 0.00035767"/>
      <mass value="0.00693606"/>
      <inertia ixx="0.00000057" ixy="0.0" ixz="0.0" iyy="0.00000084" iyz="0.0" izz="0.00000053"/>
    </inertial>
    <!-- FOOT VISUAL -->
    <visual>
      <origin rpy="0 0 0" xyz="0 0 0"/>
      <geometry>
        <mesh filename="package://solo_description/meshes/stl/with_foot/solo_foot.stl"/>
      </geometry>
      <material name="grey">
        <color rgba="0.8 0.8 0.8 1.0"/>
      </material>
    </visual>
    <!-- FOOT COLLISION -->
    <collision>
      <origin rpy="0 0 0" xyz="0 0 0"/>
      <geometry>
        <mesh filename="package://solo_description/meshes/stl/with_foot/solo_foot.stl"/>
      </geometry>
      <material name="grey">
        <color rgba="0.8 0.8 0.8 1.0"/>
      </material>
    </collision>
    <!-- Bullet specific paramters -->
    <contact>
      <lateral_friction value="1.0"/>
      <restitution value="0.5"/>
    </contact>
  </link>
  <!-- END LOWER LEG LINK -->
  <!-- Hip assembly -->
  <transmission name="HL_haa_trans">
    <type>transmission_interface/SimpleTransmission</type>
    <joint name="HL_haa_joint">
      <hardwareInterface>EffortJointInterface</hardwareInterface>
    </joint>
    <actuator name="HL_haa_motor">
      <hardwareInterface>EffortJointInterface</hardwareInterface>
      <mechanicalReduction>1</mechanicalReduction>
    </actuator>
  </transmission>
  <!-- Upper leg -->
  <transmission name="HL_hfe_trans">
    <type>transmission_interface/SimpleTransmission</type>
    <joint name="HL_hfe_joint">
      <hardwareInterface>EffortJointInterface</hardwareInterface>
    </joint>
    <actuator name="HL_hfe_motor">
      <hardwareInterface>EffortJointInterface</hardwareInterface>
      <mechanicalReduction>1</mechanicalReduction>
    </actuator>
  </transmission>
  <!-- Lower leg -->
  <transmission name="HL_kfe_trans">
    <type>transmission_interface/SimpleTransmission</type>
    <joint name="HL_kfe_joint">
      <hardwareInterface>EffortJointInterface</hardwareInterface>
    </joint>
    <actuator name="HL_kfe_motor">
      <hardwareInterface>EffortJointInterface</hardwareInterface>
      <mechanicalReduction>1</mechanicalReduction>
    </actuator>
  </transmission>
  <gazebo reference="HL_haa_joint">
    <provideFeedback>true</provideFeedback>
  </gazebo>
  <gazebo reference="HL_kfe_joint">
    <provideFeedback>true</provideFeedback>
  </gazebo>
  <gazebo reference="HL_hfe_joint">
    <provideFeedback>true</provideFeedback>
  </gazebo>
  <gazebo reference="HL_upperleg">
    <kp>1000000.0</kp>
    <kd>100.0</kd>
    <mu1>1.5</mu1>
    <mu2>1.5</mu2>
    <fdir1>1 0 0</fdir1>
    <maxVel>1.0</maxVel>
    <minDepth>0.00</minDepth>
  </gazebo>
  <gazebo reference="HL_lowerleg">
    <kp>1000000.0</kp>
    <kd>100.0</kd>
    <mu1>1.0</mu1>
    <mu2>1.0</mu2>
    <maxVel>1.0</maxVel>
    <maxContacts>1</maxContacts>
    <sensor name="HL_shin_contact_sensor" type="contact">
      <always_on>true</always_on>
      <update_rate>250.0</update_rate>
      <contact>
        <collision>HL_lowerleg_collision</collision>
      </contact>
      <!-- the sensor readings in terms of force torques are expressed in the lowerleg frame
                because gazebo lumps the fake footframe with the real parent link, the normals are in the world frame-->
      <plugin filename="libgazebo_ros_bumper.so" name="HL_shin_bumper">
        <bumperTopicName>/solo/HL_shin_bumper</bumperTopicName>
      </plugin>
    </sensor>
  </gazebo>
  <gazebo reference="HL_foot">
    <kp>1000000.0</kp>
    <kd>100.0</kd>
    <mu1>1.0</mu1>
    <mu2>1.0</mu2>
    <maxVel>1.0</maxVel>
    <maxContacts>1</maxContacts>
    <sensor name="HL_foot_contact_sensor" type="contact">
      <always_on>true</always_on>
      <update_rate>250.0</update_rate>
      <contact>
        <collision>HL_lowerleg_fixed_joint_lump__HL_foot_collision_1</collision>
      </contact>
      <!-- the sensor readings in terms of force torques are expressed in the lowerleg frame
                                because gazebo lumps the fake footframe with the real parent link, the normals are in the world frame-->
      <plugin filename="libgazebo_ros_bumper.so" name="HL_foot_bumper">
        <bumperTopicName>/solo/HL_foot_bumper</bumperTopicName>
        <robotNamespace>solo</robotNamespace>
      </plugin>
    </sensor>
    <material>Gazebo/Black</material>
  </gazebo>
  <joint name="HR_haa_joint" type="revolute">
    <parent link="trunk"/>
    <child link="HR_hip_assembly"/>
    <limit effort="1000" lower="-10" upper="10" velocity="1000"/>
    <!-- joints rotates around the x-axis -->
    <axis xyz="1 0 0"/>
    <origin rpy="0 0 0" xyz="-0.19 -0.1046 0"/>
    <!-- pybullet simulation parameters -->
    <dynamics damping="0.0" friction="0.0"/>
  </joint>
  <link name="HR_hip_assembly">
    <!-- create a dummy hip_assembly link to join the two joints -->
    <inertial>
      <origin rpy="0 0 0" xyz="0. 0. 0."/>
      <!-- Adding extra weight for actuator module at hip_assembly. -->
      <mass value="0.150"/>
      <inertia ixx="0.00000001" ixy="0.0" ixz="0.0" iyy="0.00000001" iyz="0" izz="0.00000001"/>
    </inertial>
  </link>
  <joint name="HR_hfe_joint" type="revolute">
    <parent link="HR_hip_assembly"/>
    <child link="HR_upper_leg"/>
    <limit effort="1000" lower="-10" upper="10" velocity="1000"/>
    <!-- joints rotates around the y-axis -->
    <axis xyz="0 1 0"/>
    <!-- placement of the joint -->
    <origin rpy="0 0 0" xyz="0 0 0"/>
    <!-- pybullet simulation parameters -->
    <dynamics damping="0.0" friction="0.0"/>
  </joint>
  <!-- UPPER LEG LINK -->
  <link name="HR_upper_leg">
    <!-- Right upper leg inertia -->
    <inertial>
      <origin rpy="0 0 0" xyz="-0.00001377 -0.01935853 -0.07870700"/>
      <mass value="0.14853845"/>
      <inertia ixx="0.00041107" ixy="0.0" ixz="0.0" iyy="0.00041193" iyz="-0.00004671" izz="0.00003024"/>
    </inertial>
    <!-- UPPER LEG LINK VISUAL -->
    <visual>
      <origin rpy="0 0 0" xyz="0 0 0"/>
      <geometry>
        <mesh filename="package://solo_description/meshes/stl/with_foot/solo_upper_leg_right_side.stl"/>
      </geometry>
      <material name="grey">
        <color rgba="0.8 0.8 0.8 1.0"/>
      </material>
    </visual>
    <!-- UPPER LEG LINK COLLISION -->
    <collision>
      <origin rpy="0 0 0" xyz="0 0 0"/>
      <geometry>
        <mesh filename="package://solo_description/meshes/stl/with_foot/solo_upper_leg_right_side.stl"/>
      </geometry>
      <material name="grey">
        <color rgba="0.8 0.8 0.8 1.0"/>
      </material>
    </collision>
    <!-- Bullet specific paramters -->
    <contact>
      <lateral_friction value="1.0"/>
      <restitution value="0.5"/>
    </contact>
  </link>
  <!-- END UPPER LEG LINK -->
  <!-- KFE JOINT -->
  <joint name="HR_kfe_joint" type="revolute">
    <parent link="HR_upper_leg"/>
    <child link="HR_lower_leg"/>
    <limit effort="1000" lower="-10" upper="10" velocity="1000"/>
    <!-- joints rotates around the y-axis -->
    <axis xyz="0 1 0"/>
    <origin rpy="0 0 0" xyz="0 -0.03745 -0.16"/>
    <!-- pybullet simulation parameters -->
    <dynamics damping="0.0" friction="0.0"/>
  </joint>
  <!-- LOWERLEG -->
  <link name="HR_lower_leg">
    <!-- Right lower leg inertia -->
    <inertial>
      <origin rpy="0 0 0" xyz="0.0 0.00787644 -0.08928215"/>
      <mass value="0.03070001"/>
      <inertia ixx="0.00012024" ixy="0.0" ixz="0.0" iyy="0.00012029" iyz="-0.00000305" izz="0.00000216"/>
    </inertial>
    <!-- LOWER LEG LINK VISUAL -->
    <visual>
      <origin rpy="0 0 0" xyz="0 0 0"/>
      <geometry>
        <mesh filename="package://solo_description/meshes/stl/with_foot/solo_lower_leg_right_side.stl"/>
      </geometry>
      <material name="grey">
        <color rgba="0.8 0.8 0.8 1.0"/>
      </material>
    </visual>
    <!-- LOWER LEG LINK COLLISION -->
    <collision>
      <origin rpy="0 0 0" xyz="0 0 0"/>
      <geometry>
        <mesh filename="package://solo_description/meshes/stl/with_foot/solo_lower_leg_right_side.stl"/>
      </geometry>
      <material name="grey">
        <color rgba="0.8 0.8 0.8 1.0"/>
      </material>
    </collision>
    <!-- Bullet specific paramters -->
    <contact>
      <lateral_friction value="1.0"/>
      <restitution value="0.5"/>
    </contact>
  </link>
  <!-- END LOWER LEG LINK -->
  <!-- KFE: Joint between the upper leg and the lower leg -->
  <joint name="HR_ankle" type="fixed">
    <parent link="HR_lower_leg"/>
    <child link="HR_foot"/>
    <!-- Joint placement -->
    <origin rpy="0 0 0" xyz="0 0 -0.16"/>
    <!-- Limits (usefull?) -->
    <limit effort="1000" lower="-10" upper="10" velocity="1000"/>
    <!-- pybullet simulation parameters -->
    <dynamics damping="0.0" friction="0.0"/>
  </joint>
  <!-- FOOT -->
  <link name="HR_foot">
    <!-- FOOT INERTIAL -->
    <!-- This link is symmetrical left or right -->
    <inertial>
      <origin rpy="0 0 0" xyz="0 0 0.00035767"/>
      <mass value="0.00693606"/>
      <inertia ixx="0.00000057" ixy="0.0" ixz="0.0" iyy="0.00000084" iyz="0.0" izz="0.00000053"/>
    </inertial>
    <!-- FOOT VISUAL -->
    <visual>
      <origin rpy="0 0 0" xyz="0 0 0"/>
      <geometry>
        <mesh filename="package://solo_description/meshes/stl/with_foot/solo_foot.stl"/>
      </geometry>
      <material name="grey">
        <color rgba="0.8 0.8 0.8 1.0"/>
      </material>
    </visual>
    <!-- FOOT COLLISION -->
    <collision>
      <origin rpy="0 0 0" xyz="0 0 0"/>
      <geometry>
        <mesh filename="package://solo_description/meshes/stl/with_foot/solo_foot.stl"/>
      </geometry>
      <material name="grey">
        <color rgba="0.8 0.8 0.8 1.0"/>
      </material>
    </collision>
    <!-- Bullet specific paramters -->
    <contact>
      <lateral_friction value="1.0"/>
      <restitution value="0.5"/>
    </contact>
  </link>
  <!-- END LOWER LEG LINK -->
  <!-- Hip assembly -->
  <transmission name="HR_haa_trans">
    <type>transmission_interface/SimpleTransmission</type>
    <joint name="HR_haa_joint">
      <hardwareInterface>EffortJointInterface</hardwareInterface>
    </joint>
    <actuator name="HR_haa_motor">
      <hardwareInterface>EffortJointInterface</hardwareInterface>
      <mechanicalReduction>1</mechanicalReduction>
    </actuator>
  </transmission>
  <!-- Upper leg -->
  <transmission name="HR_hfe_trans">
    <type>transmission_interface/SimpleTransmission</type>
    <joint name="HR_hfe_joint">
      <hardwareInterface>EffortJointInterface</hardwareInterface>
    </joint>
    <actuator name="HR_hfe_motor">
      <hardwareInterface>EffortJointInterface</hardwareInterface>
      <mechanicalReduction>1</mechanicalReduction>
    </actuator>
  </transmission>
  <!-- Lower leg -->
  <transmission name="HR_kfe_trans">
    <type>transmission_interface/SimpleTransmission</type>
    <joint name="HR_kfe_joint">
      <hardwareInterface>EffortJointInterface</hardwareInterface>
    </joint>
    <actuator name="HR_kfe_motor">
      <hardwareInterface>EffortJointInterface</hardwareInterface>
      <mechanicalReduction>1</mechanicalReduction>
    </actuator>
  </transmission>
  <gazebo reference="HR_haa_joint">
    <provideFeedback>true</provideFeedback>
  </gazebo>
  <gazebo reference="HR_kfe_joint">
    <provideFeedback>true</provideFeedback>
  </gazebo>
  <gazebo reference="HR_hfe_joint">
    <provideFeedback>true</provideFeedback>
  </gazebo>
  <gazebo reference="HR_upperleg">
    <kp>1000000.0</kp>
    <kd>100.0</kd>
    <mu1>1.5</mu1>
    <mu2>1.5</mu2>
    <fdir1>1 0 0</fdir1>
    <maxVel>1.0</maxVel>
    <minDepth>0.00</minDepth>
  </gazebo>
  <gazebo reference="HR_lowerleg">
    <kp>1000000.0</kp>
    <kd>100.0</kd>
    <mu1>1.0</mu1>
    <mu2>1.0</mu2>
    <maxVel>1.0</maxVel>
    <maxContacts>1</maxContacts>
    <sensor name="HR_shin_contact_sensor" type="contact">
      <always_on>true</always_on>
      <update_rate>250.0</update_rate>
      <contact>
        <collision>HR_lowerleg_collision</collision>
      </contact>
      <!-- the sensor readings in terms of force torques are expressed in the lowerleg frame
                because gazebo lumps the fake footframe with the real parent link, the normals are in the world frame-->
      <plugin filename="libgazebo_ros_bumper.so" name="HR_shin_bumper">
        <bumperTopicName>/solo/HR_shin_bumper</bumperTopicName>
      </plugin>
    </sensor>
  </gazebo>
  <gazebo reference="HR_foot">
    <kp>1000000.0</kp>
    <kd>100.0</kd>
    <mu1>1.0</mu1>
    <mu2>1.0</mu2>
    <maxVel>1.0</maxVel>
    <maxContacts>1</maxContacts>
    <sensor name="HR_foot_contact_sensor" type="contact">
      <always_on>true</always_on>
      <update_rate>250.0</update_rate>
      <contact>
        <collision>HR_lowerleg_fixed_joint_lump__HR_foot_collision_1</collision>
      </contact>
      <!-- the sensor readings in terms of force torques are expressed in the lowerleg frame
                                because gazebo lumps the fake footframe with the real parent link, the normals are in the world frame-->
      <plugin filename="libgazebo_ros_bumper.so" name="HR_foot_bumper">
        <bumperTopicName>/solo/HR_foot_bumper</bumperTopicName>
        <robotNamespace>solo</robotNamespace>
      </plugin>
    </sensor>
    <material>Gazebo/Black</material>
  </gazebo>
</robot>
