<?xml version="1.0" ?>
<!-- =================================================================================== -->
<!-- |    This document was autogenerated by xacro from /home/mfocchi/ros_ws/install/share/solo_fw_description/robots/solo_fw.urdf.xacro | -->
<!-- |    EDITING THIS FILE BY HAND IS NOT RECOMMENDED                                 | -->
<!-- =================================================================================== -->
<robot name="solo_fw">
  <gazebo>
    <plugin filename="libgazebo_ros_control.so" name="gazebo_ros_controller_manager">
      <!-- if task_period is smaller than sim max_step_size (in world file) it is clamped to that value!!!!!!-->
      <robotNamespace>/solo_fw</robotNamespace>
      <robotSimType>gazebo_ros_control/DefaultRobotHWSim</robotSimType>
      <legacyModeNS>true</legacyModeNS>
      <controlPeriod>0.004</controlPeriod>
    </plugin>
    <plugin filename="libgazebo_ros_p3d.so" name="gazebo_ros_p3d">
      <robotNamespace>/solo_fw</robotNamespace>
      <bodyName>trunk</bodyName>
      <topicName>ground_truth</topicName>
      <frameName>world</frameName>
      <xyzOffsets>0 0 0</xyzOffsets>
      <rpyOffsets>0 0 0</rpyOffsets>
      <gaussianNoise>0</gaussianNoise>
      <alwaysOn>true</alwaysOn>
      <updateRate>250.0</updateRate>
    </plugin>
  </gazebo>
  <!-- BASE LINK -->
  <!-- floating type is supported in older versions of Gazebo. In new Gazebo if a link has no parent, it is supposed to be attached to a floating joint -->
  <!-- Floating-base Joint -->
  <link name="world"/>
  <joint name="floating_base_joint" type="floating">
    <origin rpy="0 0 0" xyz="0 0 0"/>
    <parent link="world"/>
    <child link="base_link"/>
  </joint>
  <link name="base_link"/>
  <joint name="floating_base" type="fixed">
    <origin rpy="0 0 0" xyz="0 0 0"/>
    <parent link="base_link"/>
    <child link="trunk"/>
  </joint>
  <link name="trunk">
    <inertial>
      <origin rpy="0 0 0" xyz="0 0 0"/>
      <mass value="1.16115091"/>
      <!-- The base is extremely symmetrical. -->
      <inertia ixx="0.00578574" ixy="0.0" ixz="0.0" iyy="0.01938108" iyz="0.0" izz="0.02476124"/>
    </inertial>
    <visual>
      <origin rpy="0 0 0" xyz="0 0 0"/>
      <geometry>
        <mesh filename="package://solo_description/meshes/stl/with_foot/solo_body.stl"/>
      </geometry>
      <material name="grey">
        <color rgba="0.8 0.8 0.8 1.0"/>
      </material>
    </visual>
    <collision>
      <origin rpy="0 0 0" xyz="0 0 0"/>
      <geometry>
        <mesh filename="package://solo_description/meshes/stl/with_foot/solo_body.stl"/>
      </geometry>
      <material name="grey">
        <color rgba="0.8 0.8 0.8 1.0"/>
      </material>
    </collision>
    <!-- Bullet specific paramters -->
    <contact>
      <lateral_friction value="1.0"/>
      <restitution value="0.5"/>
    </contact>
  </link>
  <!--HAA JOINT: Joint between the trunk and the hip assembly -->
  <joint name="lf_haa_joint" type="revolute">
    <parent link="trunk"/>
    <child link="lf_hip_assembly"/>
    <!-- joints rotates around the x-axis -->
    <axis xyz="1 0 0"/>
    <!-- limit and placement of the joint -->
    <!-- LF_HAA_JOINT -->
    <!-- lower=-75deg, upper=140, velocity=555.5rpm (=5000rpm motor-side) -->
    <limit effort="1.575" lower="-1.30899694" upper="2.44346095" velocity="58.17764173"/>
    <origin rpy="0 0 0" xyz="0.1946 0.08750000000000001 0"/>
    <!-- pybullet simulation parameters -->
    <dynamics damping="0.0" friction="0.0"/>
  </joint>
  <!-- HIP ASSEMBLY -->
  <link name="lf_hip_assembly">
    <!-- create a dummy hip_assembly link to join the two joints -->
    <!-- HIP ASSEMBLY VISUAL-->
    <visual>
      <!-- LF HIP ASSEMBLY -->
      <origin rpy="0 0 0" xyz="0.01950 0 0"/>
      <geometry>
        <mesh filename="package://solo_description/meshes/stl/solo12/solo12_hip_fe_fl.stl"/>
      </geometry>
      <material name="grey">
        <color rgba="0.8 0.8 0.8 1.0"/>
      </material>
    </visual>
    <!-- HIP ASSEMBLY COLLISION-->
    <collision>
      <!-- LF HIP ASSEMBLY -->
      <origin rpy="0 0 0" xyz="0.01950 0 0"/>
      <geometry>
        <mesh filename="package://solo_description/meshes/stl/solo12/solo12_hip_fe_fl.stl"/>
      </geometry>
      <material name="grey">
        <color rgba="0.8 0.8 0.8 1.0"/>
        xacro
                	
      </material>
    </collision>
    <!-- HIP ASSEMBLY INERTIAL -->
    <inertial>
      <mass value="0.14853845"/>
      <!-- LF HIP ASSEMBLY -->
      <origin rpy="0 0 0" xyz="-0.07870700 0.01 0."/>
      <inertia ixx="0.00003024" ixy="0.00004671" ixz="0.0" iyy="0.00041193" iyz="0.0" izz="0.00041107"/>
    </inertial>
  </link>
  <!--HFE JOINT-->
  <joint name="lf_hfe_joint" type="revolute">
    <parent link="lf_hip_assembly"/>
    <child link="lf_upperleg"/>
    <!-- joints rotates around the y-axis -->
    <axis xyz="0 1 0"/>
    <!-- LF_HFE_JOINT -->
    <!-- lower=-225deg, upper=90deg, velocity=555.5rpm (=5000rpm motor-side) -->
    <limit effort="1.575" lower="-3.92699082" upper="1.57079633" velocity="58.17764173"/>
    <origin rpy="0 0 0" xyz="0 0.014 0"/>
    <!-- pybullet simulation parameters -->
    <dynamics damping="0.0" friction="0.0"/>
  </joint>
  <!-- UPPER LEG LINK -->
  <link name="lf_upperleg">
    <!-- Left upper leg inertia -->
    <inertial>
      <origin rpy="0 0 0" xyz="0.00001377 0.01935853 -0.07870700"/>
      <mass value="0.14853845"/>
      <inertia ixx="0.00041107" ixy="0.0" ixz="0.0" iyy="0.00041193" iyz="0.00004671" izz="0.00003024"/>
    </inertial>
    <!-- UPPER LEG LINK VISUAL -->
    <visual>
      <origin rpy="0 0 0" xyz="0 0 0"/>
      <geometry>
        <mesh filename="package://solo_description/meshes/stl/with_foot/solo_upper_leg_left_side.stl"/>
      </geometry>
      <material name="grey">
        <color rgba="0.8 0.8 0.8 1.0"/>
      </material>
    </visual>
    <!-- UPPER LEG LINK COLLISION -->
    <collision>
      <origin rpy="0 0 0" xyz="0 0 0"/>
      <geometry>
        <mesh filename="package://solo_description/meshes/stl/with_foot/solo_upper_leg_left_side.stl"/>
      </geometry>
      <material name="grey">
        <color rgba="0.8 0.8 0.8 1.0"/>
      </material>
    </collision>
    <!-- Bullet specific paramters -->
    <contact>
      <lateral_friction value="1.0"/>
      <restitution value="0.5"/>
    </contact>
  </link>
  <!-- END UPPER LEG LINK -->
  <!-- KFE JOINT: Joint between the upper leg and the lower leg -->
  <joint name="lf_kfe_joint" type="revolute">
    <parent link="lf_upperleg"/>
    <child link="lf_lowerleg"/>
    <!-- joints rotates around the y-axis -->
    <axis xyz="0 1 0"/>
    <!-- LF_KFE JOINT -->
    <!-- lower=-370deg, upper=370deg, velocity=555.5rpm (=5000rpm motor-side) -->
    <limit effort="1.575" lower="-6.45771823" upper="6.45771823" velocity="58.17764173"/>
    <origin rpy="0 0 0" xyz="0 0.037450000000000004 -0.16"/>
    <!-- pybullet simulation parameters -->
    <dynamics damping="0.0" friction="0.0"/>
  </joint>
  <!-- LOWERLEG -->
  <link name="lf_lowerleg">
    <!-- Left lower leg inertia -->
    <inertial>
      <origin rpy="0 0 0" xyz="0.0 0.00787644 -0.08928215"/>
      <mass value="0.03070001"/>
      <inertia ixx="0.00012024" ixy="0.0" ixz="0.0" iyy="0.00012029" iyz="0.00000305" izz="0.00000216"/>
    </inertial>
    <!-- LOWER LEG LINK VISUAL -->
    <visual>
      <origin rpy="0 0 0" xyz="0 0 0"/>
      <geometry>
        <mesh filename="package://solo_description/meshes/stl/with_foot/solo_lower_leg_left_side.stl"/>
      </geometry>
      <material name="grey">
        <color rgba="0.8 0.8 0.8 1.0"/>
      </material>
    </visual>
    <!-- LOWER LEG LINK COLLISION -->
    <collision>
      <origin rpy="0 0 0" xyz="0 0 0"/>
      <geometry>
        <mesh filename="package://solo_description/meshes/stl/with_foot/solo_lower_leg_left_side.stl"/>
      </geometry>
      <material name="grey">
        <color rgba="0.8 0.8 0.8 1.0"/>
      </material>
    </collision>
    <!-- Bullet specific paramters -->
    <contact>
      <lateral_friction value="1.0"/>
      <restitution value="0.5"/>
    </contact>
  </link>
  <!-- END LOWER LEG LINK -->
  <!-- ANKLE: (Fixed) joint between the lower leg and the foot -->
  <joint name="lf_ankle" type="fixed">
    <parent link="lf_lowerleg"/>
    <child link="lf_foot"/>
    <origin rpy="0 0 0" xyz="0 0.008 -0.16"/>
    <!-- pybullet simulation parameters -->
    <dynamics damping="0.0" friction="0.0"/>
  </joint>
  <!-- FOOT -->
  <link name="lf_foot">
    <!-- FOOT INERTIAL -->
    <!-- This link is symmetrical left or right -->
    <inertial>
      <origin rpy="0 0 0" xyz="0 0 0.00035767"/>
      <mass value="0.00693606"/>
      <inertia ixx="0.00000057" ixy="0.0" ixz="0.0" iyy="0.00000084" iyz="0.0" izz="0.00000053"/>
    </inertial>
    <!-- FOOT VISUAL -->
    <visual>
      <origin rpy="0 0 0" xyz="0 0 0"/>
      <geometry>
        <mesh filename="package://solo_description/meshes/stl/with_foot/solo_foot.stl"/>
      </geometry>
      <material name="grey">
        <color rgba="0.8 0.8 0.8 1.0"/>
      </material>
    </visual>
    <!-- FOOT COLLISION -->
    <collision>
      <origin rpy="0 0 0" xyz="0 0 0"/>
      <geometry>
        <mesh filename="package://solo_description/meshes/stl/with_foot/solo_foot.stl"/>
        <!-- sphere radius="0.01"/-->
      </geometry>
      <material name="grey">
        <color rgba="0.8 0.8 0.8 1.0"/>
      </material>
    </collision>
    <!-- Bullet specific paramters -->
    <contact>
      <lateral_friction value="1.0"/>
      <restitution value="0.5"/>
    </contact>
  </link>
  <!-- END FOOT LINK -->
  <!-- Hip assembly -->
  <transmission name="lf_haa_trans">
    <type>transmission_interface/SimpleTransmission</type>
    <joint name="lf_haa_joint">
      <hardwareInterface>hardware_interface/EffortJointInterface</hardwareInterface>
    </joint>
    <actuator name="lf_haa_motor">
      <hardwareInterface>hardware_interface/EffortJointInterface</hardwareInterface>
      <mechanicalReduction>1</mechanicalReduction>
    </actuator>
  </transmission>
  <!-- Upper leg -->
  <transmission name="lf_hfe_trans">
    <type>transmission_interface/SimpleTransmission</type>
    <joint name="lf_hfe_joint">
      <hardwareInterface>hardware_interface/EffortJointInterface</hardwareInterface>
    </joint>
    <actuator name="lf_hfe_motor">
      <hardwareInterface>hardware_interface/EffortJointInterface</hardwareInterface>
      <mechanicalReduction>1</mechanicalReduction>
    </actuator>
  </transmission>
  <!-- Lower leg -->
  <transmission name="lf_kfe_trans">
    <type>transmission_interface/SimpleTransmission</type>
    <joint name="lf_kfe_joint">
      <hardwareInterface>hardware_interface/EffortJointInterface</hardwareInterface>
    </joint>
    <actuator name="lf_kfe_motor">
      <hardwareInterface>hardware_interface/EffortJointInterface</hardwareInterface>
      <mechanicalReduction>1</mechanicalReduction>
    </actuator>
  </transmission>
  <gazebo reference="lf_haa_joint">
    <provideFeedback>true</provideFeedback>
  </gazebo>
  <gazebo reference="lf_kfe_joint">
    <provideFeedback>true</provideFeedback>
  </gazebo>
  <gazebo reference="lf_hfe_joint">
    <provideFeedback>true</provideFeedback>
  </gazebo>
  <gazebo reference="lf_upperleg">
    <kp>1000000.0</kp>
    <kd>100.0</kd>
    <mu1>1.5</mu1>
    <mu2>1.5</mu2>
    <fdir1>1 0 0</fdir1>
    <maxVel>1.0</maxVel>
    <minDepth>0.00</minDepth>
  </gazebo>
  <gazebo reference="lf_lowerleg">
    <kp>1000000.0</kp>
    <kd>100.0</kd>
    <mu1>1.0</mu1>
    <mu2>1.0</mu2>
    <maxVel>1.0</maxVel>
    <maxContacts>1</maxContacts>
    <sensor name="lf_shin_contact_sensor" type="contact">
      <always_on>true</always_on>
      <update_rate>250.0</update_rate>
      <contact>
        <collision>lf_lowerleg_collision</collision>
      </contact>
      <!-- the sensor readings in terms of force torques are expressed in the lowerleg frame
                because gazebo lumps the fake footframe with the real parent link, the normals are in the world frame-->
      <plugin filename="libgazebo_ros_bumper.so" name="lf_shin_bumper">
        <bumperTopicName>/solo_fw/lf_shin_bumper</bumperTopicName>
      </plugin>
    </sensor>
  </gazebo>
  <gazebo reference="lf_foot">
    <kp>1000000.0</kp>
    <kd>100.0</kd>
    <mu1>0.8</mu1>
    <mu2>0.8</mu2>
    <maxVel>1.0</maxVel>
    <maxContacts>1</maxContacts>
    <sensor name="lf_foot_contact_sensor" type="contact">
      <always_on>true</always_on>
      <update_rate>1000.0</update_rate>
      <contact>
        <collision>lf_lowerleg_fixed_joint_lump__lf_foot_collision_1</collision>
      </contact>
      <!-- the sensor readings in terms of force torques are expressed in the lowerleg frame
                                because gazebo lumps the fake footframe with the real parent link, the normals are in the world frame-->
      <plugin filename="libgazebo_ros_bumper.so" name="lf_foot_bumper">
        <bumperTopicName>/solo_fw/lf_foot_bumper</bumperTopicName>
        <!--robotNamespace>solo</robotNamespace-->
        <frameName>lf_foot</frameName>
      </plugin>
    </sensor>
    <material>Gazebo/Black</material>
  </gazebo>
  <!--HAA JOINT: Joint between the trunk and the hip assembly -->
  <joint name="rf_haa_joint" type="revolute">
    <parent link="trunk"/>
    <child link="rf_hip_assembly"/>
    <!-- joints rotates around the x-axis -->
    <axis xyz="1 0 0"/>
    <!-- limit and placement of the joint -->
    <!-- RF_HAA_JOINT -->
    <!-- lower=-140deg, upper=75, velocity=555.5rpm (=5000rpm motor-side) -->
    <limit effort="1.575" lower="-2.44346095" upper="1.30899694" velocity="58.17764173"/>
    <origin rpy="0 0 0" xyz="0.1946 -0.08750000000000001 0"/>
    <!-- pybullet simulation parameters -->
    <dynamics damping="0.0" friction="0.0"/>
  </joint>
  <!-- HIP ASSEMBLY -->
  <link name="rf_hip_assembly">
    <!-- create a dummy hip_assembly link to join the two joints -->
    <!-- HIP ASSEMBLY VISUAL-->
    <visual>
      <!-- RF HIP ASSEMBLY -->
      <origin rpy="0 0 0" xyz="0.01950 0 0"/>
      <geometry>
        <mesh filename="package://solo_description/meshes/stl/solo12/solo12_hip_fe_fr.stl"/>
      </geometry>
      <material name="grey">
        <color rgba="0.8 0.8 0.8 1.0"/>
      </material>
    </visual>
    <!-- HIP ASSEMBLY COLLISION-->
    <collision>
      <!-- RF HIP ASSEMBLY -->
      <origin rpy="0 0 0" xyz="0.01950 0 0"/>
      <geometry>
        <mesh filename="package://solo_description/meshes/stl/solo12/solo12_hip_fe_fr.stl"/>
      </geometry>
      <material name="grey">
        <color rgba="0.8 0.8 0.8 1.0"/>
        xacro
                	
      </material>
    </collision>
    <!-- HIP ASSEMBLY INERTIAL -->
    <inertial>
      <mass value="0.14853845"/>
      <!-- RF HIP ASSEMBLY -->
      <origin rpy="0 0 0" xyz="-0.07870700 -0.01 0."/>
      <inertia ixx="0.00003024" ixy="-0.00004671" ixz="0.0" iyy="0.00041193" iyz="0.0" izz="0.00041107"/>
    </inertial>
  </link>
  <!--HFE JOINT-->
  <joint name="rf_hfe_joint" type="revolute">
    <parent link="rf_hip_assembly"/>
    <child link="rf_upperleg"/>
    <!-- joints rotates around the y-axis -->
    <axis xyz="0 1 0"/>
    <!-- RF_HFE_JOINT -->
    <!-- lower=-225deg, upper=90deg, velocity=555.5rpm (=5000rpm motor-side) -->
    <limit effort="1.575" lower="-3.92699082" upper="1.57079633" velocity="58.17764173"/>
    <origin rpy="0 0 0" xyz="0 -0.014 0"/>
    <!-- pybullet simulation parameters -->
    <dynamics damping="0.0" friction="0.0"/>
  </joint>
  <!-- UPPER LEG LINK -->
  <link name="rf_upperleg">
    <!-- Right upper leg inertia -->
    <inertial>
      <origin rpy="0 0 0" xyz="-0.00001377 -0.01935853 -0.07870700"/>
      <mass value="0.14853845"/>
      <inertia ixx="0.00041107" ixy="0.0" ixz="0.0" iyy="0.00041193" iyz="-0.00004671" izz="0.00003024"/>
    </inertial>
    <!-- UPPER LEG LINK VISUAL -->
    <visual>
      <origin rpy="0 0 0" xyz="0 0 0"/>
      <geometry>
        <mesh filename="package://solo_description/meshes/stl/with_foot/solo_upper_leg_right_side.stl"/>
      </geometry>
      <material name="grey">
        <color rgba="0.8 0.8 0.8 1.0"/>
      </material>
    </visual>
    <!-- UPPER LEG LINK COLLISION -->
    <collision>
      <origin rpy="0 0 0" xyz="0 0 0"/>
      <geometry>
        <mesh filename="package://solo_description/meshes/stl/with_foot/solo_upper_leg_right_side.stl"/>
      </geometry>
      <material name="grey">
        <color rgba="0.8 0.8 0.8 1.0"/>
      </material>
    </collision>
    <!-- Bullet specific paramters -->
    <contact>
      <lateral_friction value="1.0"/>
      <restitution value="0.5"/>
    </contact>
  </link>
  <!-- END UPPER LEG LINK -->
  <!-- KFE JOINT: Joint between the upper leg and the lower leg -->
  <joint name="rf_kfe_joint" type="revolute">
    <parent link="rf_upperleg"/>
    <child link="rf_lowerleg"/>
    <!-- joints rotates around the y-axis -->
    <axis xyz="0 1 0"/>
    <!-- RF_KFE JOINT -->
    <!-- lower=-370deg, upper=370deg, velocity=555.5rpm (=5000rpm motor-side) -->
    <limit effort="1.575" lower="-6.45771823" upper="6.45771823" velocity="58.17764173"/>
    <origin rpy="0 0 0" xyz="0 -0.037450000000000004 -0.16"/>
    <!-- pybullet simulation parameters -->
    <dynamics damping="0.0" friction="0.0"/>
  </joint>
  <!-- LOWERLEG -->
  <link name="rf_lowerleg">
    <!-- Right lower leg inertia -->
    <inertial>
      <origin rpy="0 0 0" xyz="0.0 0.00787644 -0.08928215"/>
      <mass value="0.03070001"/>
      <inertia ixx="0.00012024" ixy="0.0" ixz="0.0" iyy="0.00012029" iyz="-0.00000305" izz="0.00000216"/>
    </inertial>
    <!-- LOWER LEG LINK VISUAL -->
    <visual>
      <origin rpy="0 0 0" xyz="0 0 0"/>
      <geometry>
        <mesh filename="package://solo_description/meshes/stl/with_foot/solo_lower_leg_right_side.stl"/>
      </geometry>
      <material name="grey">
        <color rgba="0.8 0.8 0.8 1.0"/>
      </material>
    </visual>
    <!-- LOWER LEG LINK COLLISION -->
    <collision>
      <origin rpy="0 0 0" xyz="0 0 0"/>
      <geometry>
        <mesh filename="package://solo_description/meshes/stl/with_foot/solo_lower_leg_right_side.stl"/>
      </geometry>
      <material name="grey">
        <color rgba="0.8 0.8 0.8 1.0"/>
      </material>
    </collision>
    <!-- Bullet specific paramters -->
    <contact>
      <lateral_friction value="1.0"/>
      <restitution value="0.5"/>
    </contact>
  </link>
  <!-- END LOWER LEG LINK -->
  <!-- ANKLE: (Fixed) joint between the lower leg and the foot -->
  <joint name="rf_ankle" type="fixed">
    <parent link="rf_lowerleg"/>
    <child link="rf_foot"/>
    <origin rpy="0 0 0" xyz="0 -0.008 -0.16"/>
    <!-- pybullet simulation parameters -->
    <dynamics damping="0.0" friction="0.0"/>
  </joint>
  <!-- FOOT -->
  <link name="rf_foot">
    <!-- FOOT INERTIAL -->
    <!-- This link is symmetrical left or right -->
    <inertial>
      <origin rpy="0 0 0" xyz="0 0 0.00035767"/>
      <mass value="0.00693606"/>
      <inertia ixx="0.00000057" ixy="0.0" ixz="0.0" iyy="0.00000084" iyz="0.0" izz="0.00000053"/>
    </inertial>
    <!-- FOOT VISUAL -->
    <visual>
      <origin rpy="0 0 0" xyz="0 0 0"/>
      <geometry>
        <mesh filename="package://solo_description/meshes/stl/with_foot/solo_foot.stl"/>
      </geometry>
      <material name="grey">
        <color rgba="0.8 0.8 0.8 1.0"/>
      </material>
    </visual>
    <!-- FOOT COLLISION -->
    <collision>
      <origin rpy="0 0 0" xyz="0 0 0"/>
      <geometry>
        <mesh filename="package://solo_description/meshes/stl/with_foot/solo_foot.stl"/>
        <!-- sphere radius="0.01"/-->
      </geometry>
      <material name="grey">
        <color rgba="0.8 0.8 0.8 1.0"/>
      </material>
    </collision>
    <!-- Bullet specific paramters -->
    <contact>
      <lateral_friction value="1.0"/>
      <restitution value="0.5"/>
    </contact>
  </link>
  <!-- END FOOT LINK -->
  <!-- Hip assembly -->
  <transmission name="rf_haa_trans">
    <type>transmission_interface/SimpleTransmission</type>
    <joint name="rf_haa_joint">
      <hardwareInterface>hardware_interface/EffortJointInterface</hardwareInterface>
    </joint>
    <actuator name="rf_haa_motor">
      <hardwareInterface>hardware_interface/EffortJointInterface</hardwareInterface>
      <mechanicalReduction>1</mechanicalReduction>
    </actuator>
  </transmission>
  <!-- Upper leg -->
  <transmission name="rf_hfe_trans">
    <type>transmission_interface/SimpleTransmission</type>
    <joint name="rf_hfe_joint">
      <hardwareInterface>hardware_interface/EffortJointInterface</hardwareInterface>
    </joint>
    <actuator name="rf_hfe_motor">
      <hardwareInterface>hardware_interface/EffortJointInterface</hardwareInterface>
      <mechanicalReduction>1</mechanicalReduction>
    </actuator>
  </transmission>
  <!-- Lower leg -->
  <transmission name="rf_kfe_trans">
    <type>transmission_interface/SimpleTransmission</type>
    <joint name="rf_kfe_joint">
      <hardwareInterface>hardware_interface/EffortJointInterface</hardwareInterface>
    </joint>
    <actuator name="rf_kfe_motor">
      <hardwareInterface>hardware_interface/EffortJointInterface</hardwareInterface>
      <mechanicalReduction>1</mechanicalReduction>
    </actuator>
  </transmission>
  <gazebo reference="rf_haa_joint">
    <provideFeedback>true</provideFeedback>
  </gazebo>
  <gazebo reference="rf_kfe_joint">
    <provideFeedback>true</provideFeedback>
  </gazebo>
  <gazebo reference="rf_hfe_joint">
    <provideFeedback>true</provideFeedback>
  </gazebo>
  <gazebo reference="rf_upperleg">
    <kp>1000000.0</kp>
    <kd>100.0</kd>
    <mu1>1.5</mu1>
    <mu2>1.5</mu2>
    <fdir1>1 0 0</fdir1>
    <maxVel>1.0</maxVel>
    <minDepth>0.00</minDepth>
  </gazebo>
  <gazebo reference="rf_lowerleg">
    <kp>1000000.0</kp>
    <kd>100.0</kd>
    <mu1>1.0</mu1>
    <mu2>1.0</mu2>
    <maxVel>1.0</maxVel>
    <maxContacts>1</maxContacts>
    <sensor name="rf_shin_contact_sensor" type="contact">
      <always_on>true</always_on>
      <update_rate>250.0</update_rate>
      <contact>
        <collision>rf_lowerleg_collision</collision>
      </contact>
      <!-- the sensor readings in terms of force torques are expressed in the lowerleg frame
                because gazebo lumps the fake footframe with the real parent link, the normals are in the world frame-->
      <plugin filename="libgazebo_ros_bumper.so" name="rf_shin_bumper">
        <bumperTopicName>/solo_fw/rf_shin_bumper</bumperTopicName>
      </plugin>
    </sensor>
  </gazebo>
  <gazebo reference="rf_foot">
    <kp>1000000.0</kp>
    <kd>100.0</kd>
    <mu1>0.8</mu1>
    <mu2>0.8</mu2>
    <maxVel>1.0</maxVel>
    <maxContacts>1</maxContacts>
    <sensor name="rf_foot_contact_sensor" type="contact">
      <always_on>true</always_on>
      <update_rate>1000.0</update_rate>
      <contact>
        <collision>rf_lowerleg_fixed_joint_lump__rf_foot_collision_1</collision>
      </contact>
      <!-- the sensor readings in terms of force torques are expressed in the lowerleg frame
                                because gazebo lumps the fake footframe with the real parent link, the normals are in the world frame-->
      <plugin filename="libgazebo_ros_bumper.so" name="rf_foot_bumper">
        <bumperTopicName>/solo_fw/rf_foot_bumper</bumperTopicName>
        <!--robotNamespace>solo</robotNamespace-->
        <frameName>rf_foot</frameName>
      </plugin>
    </sensor>
    <material>Gazebo/Black</material>
  </gazebo>
  <!--HAA JOINT: Joint between the trunk and the hip assembly -->
  <joint name="lh_haa_joint" type="revolute">
    <parent link="trunk"/>
    <child link="lh_hip_assembly"/>
    <!-- joints rotates around the x-axis -->
    <axis xyz="1 0 0"/>
    <!-- limit and placement of the joint -->
    <!-- LH_HAA_JOINT -->
    <!-- lower=-75deg, upper=140, velocity=555.5rpm (=5000rpm motor-side) -->
    <limit effort="1.575" lower="-1.30899694" upper="2.44346095" velocity="58.17764173"/>
    <origin rpy="0 0 0" xyz="-0.1946 0.08750000000000001 0"/>
    <!-- pybullet simulation parameters -->
    <dynamics damping="0.0" friction="0.0"/>
  </joint>
  <!-- HIP ASSEMBLY -->
  <link name="lh_hip_assembly">
    <!-- create a dummy hip_assembly link to join the two joints -->
    <!-- HIP ASSEMBLY VISUAL-->
    <visual>
      <!-- LH HIP ASSEMBLY -->
      <origin rpy="0 0 0" xyz="-0.01950 0 0"/>
      <geometry>
        <mesh filename="package://solo_description/meshes/stl/solo12/solo12_hip_fe_hl.stl"/>
      </geometry>
      <material name="grey">
        <color rgba="0.8 0.8 0.8 1.0"/>
      </material>
    </visual>
    <!-- HIP ASSEMBLY COLLISION-->
    <collision>
      <!-- LH HIP ASSEMBLY -->
      <origin rpy="0 0 0" xyz="-0.01950 0 0"/>
      <geometry>
        <mesh filename="package://solo_description/meshes/stl/solo12/solo12_hip_fe_hl.stl"/>
      </geometry>
      <material name="grey">
        <color rgba="0.8 0.8 0.8 1.0"/>
        xacro
                	
      </material>
    </collision>
    <!-- HIP ASSEMBLY INERTIAL -->
    <inertial>
      <mass value="0.14853845"/>
      <!-- LH HIP ASSEMBLY -->
      <origin rpy="0 0 0" xyz="0.07870700 0.01 0."/>
      <inertia ixx="0.00003024" ixy="0.00004671" ixz="0.0" iyy="0.00041193" iyz="0.0" izz="0.00041107"/>
    </inertial>
  </link>
  <!--HFE JOINT-->
  <joint name="lh_hfe_joint" type="revolute">
    <parent link="lh_hip_assembly"/>
    <child link="lh_upperleg"/>
    <!-- joints rotates around the y-axis -->
    <axis xyz="0 1 0"/>
    <!-- LH_HFE_JOINT -->
    <!-- lower=-90deg, upper=225deg, velocity=555.5rpm (=5000rpm motor-side) -->
    <limit effort="1.575" lower="-1.57079633" upper="3.92699082" velocity="58.17764173"/>
    <origin rpy="0 0 0" xyz="0 0.014 0"/>
    <!-- pybullet simulation parameters -->
    <dynamics damping="0.0" friction="0.0"/>
  </joint>
  <!-- UPPER LEG LINK -->
  <link name="lh_upperleg">
    <!-- Left upper leg inertia -->
    <inertial>
      <origin rpy="0 0 0" xyz="0.00001377 0.01935853 -0.07870700"/>
      <mass value="0.14853845"/>
      <inertia ixx="0.00041107" ixy="0.0" ixz="0.0" iyy="0.00041193" iyz="0.00004671" izz="0.00003024"/>
    </inertial>
    <!-- UPPER LEG LINK VISUAL -->
    <visual>
      <origin rpy="0 0 0" xyz="0 0 0"/>
      <geometry>
        <mesh filename="package://solo_description/meshes/stl/with_foot/solo_upper_leg_left_side.stl"/>
      </geometry>
      <material name="grey">
        <color rgba="0.8 0.8 0.8 1.0"/>
      </material>
    </visual>
    <!-- UPPER LEG LINK COLLISION -->
    <collision>
      <origin rpy="0 0 0" xyz="0 0 0"/>
      <geometry>
        <mesh filename="package://solo_description/meshes/stl/with_foot/solo_upper_leg_left_side.stl"/>
      </geometry>
      <material name="grey">
        <color rgba="0.8 0.8 0.8 1.0"/>
      </material>
    </collision>
    <!-- Bullet specific paramters -->
    <contact>
      <lateral_friction value="1.0"/>
      <restitution value="0.5"/>
    </contact>
  </link>
  <!-- END UPPER LEG LINK -->
  <!-- KFE JOINT: Joint between the upper leg and the lower leg -->
  <joint name="lh_kfe_joint" type="revolute">
    <parent link="lh_upperleg"/>
    <child link="lh_lowerleg"/>
    <!-- joints rotates around the y-axis -->
    <axis xyz="0 1 0"/>
    <!-- LH_KFE JOINT -->
    <!-- lower=-370deg, upper=370deg, velocity=555.5rpm (=5000rpm motor-side) -->
    <limit effort="1.575" lower="-6.45771823" upper="6.45771823" velocity="58.17764173"/>
    <origin rpy="0 0 0" xyz="0 0.037450000000000004 -0.16"/>
    <!-- pybullet simulation parameters -->
    <dynamics damping="0.0" friction="0.0"/>
  </joint>
  <!-- LOWERLEG -->
  <link name="lh_lowerleg">
    <!-- Left lower leg inertia -->
    <inertial>
      <origin rpy="0 0 0" xyz="0.0 0.00787644 -0.08928215"/>
      <mass value="0.03070001"/>
      <inertia ixx="0.00012024" ixy="0.0" ixz="0.0" iyy="0.00012029" iyz="0.00000305" izz="0.00000216"/>
    </inertial>
    <!-- LOWER LEG LINK VISUAL -->
    <visual>
      <origin rpy="0 0 0" xyz="0 0 0"/>
      <geometry>
        <mesh filename="package://solo_description/meshes/stl/with_foot/solo_lower_leg_left_side.stl"/>
      </geometry>
      <material name="grey">
        <color rgba="0.8 0.8 0.8 1.0"/>
      </material>
    </visual>
    <!-- LOWER LEG LINK COLLISION -->
    <collision>
      <origin rpy="0 0 0" xyz="0 0 0"/>
      <geometry>
        <mesh filename="package://solo_description/meshes/stl/with_foot/solo_lower_leg_left_side.stl"/>
      </geometry>
      <material name="grey">
        <color rgba="0.8 0.8 0.8 1.0"/>
      </material>
    </collision>
    <!-- Bullet specific paramters -->
    <contact>
      <lateral_friction value="1.0"/>
      <restitution value="0.5"/>
    </contact>
  </link>
  <!-- END LOWER LEG LINK -->
  <!-- ANKLE: (Fixed) joint between the lower leg and the foot -->
  <joint name="lh_ankle" type="fixed">
    <parent link="lh_lowerleg"/>
    <child link="lh_foot"/>
    <origin rpy="0 0 0" xyz="0 0.008 -0.16"/>
    <!-- pybullet simulation parameters -->
    <dynamics damping="0.0" friction="0.0"/>
  </joint>
  <!-- FOOT -->
  <link name="lh_foot">
    <!-- FOOT INERTIAL -->
    <!-- This link is symmetrical left or right -->
    <inertial>
      <origin rpy="0 0 0" xyz="0 0 0.00035767"/>
      <mass value="0.00693606"/>
      <inertia ixx="0.00000057" ixy="0.0" ixz="0.0" iyy="0.00000084" iyz="0.0" izz="0.00000053"/>
    </inertial>
    <!-- FOOT VISUAL -->
    <visual>
      <origin rpy="0 0 0" xyz="0 0 0"/>
      <geometry>
        <mesh filename="package://solo_description/meshes/stl/with_foot/solo_foot.stl"/>
      </geometry>
      <material name="grey">
        <color rgba="0.8 0.8 0.8 1.0"/>
      </material>
    </visual>
    <!-- FOOT COLLISION -->
    <collision>
      <origin rpy="0 0 0" xyz="0 0 0"/>
      <geometry>
        <mesh filename="package://solo_description/meshes/stl/with_foot/solo_foot.stl"/>
        <!-- sphere radius="0.01"/-->
      </geometry>
      <material name="grey">
        <color rgba="0.8 0.8 0.8 1.0"/>
      </material>
    </collision>
    <!-- Bullet specific paramters -->
    <contact>
      <lateral_friction value="1.0"/>
      <restitution value="0.5"/>
    </contact>
  </link>
  <!-- END FOOT LINK -->
  <!-- Hip assembly -->
  <transmission name="lh_haa_trans">
    <type>transmission_interface/SimpleTransmission</type>
    <joint name="lh_haa_joint">
      <hardwareInterface>hardware_interface/EffortJointInterface</hardwareInterface>
    </joint>
    <actuator name="lh_haa_motor">
      <hardwareInterface>hardware_interface/EffortJointInterface</hardwareInterface>
      <mechanicalReduction>1</mechanicalReduction>
    </actuator>
  </transmission>
  <!-- Upper leg -->
  <transmission name="lh_hfe_trans">
    <type>transmission_interface/SimpleTransmission</type>
    <joint name="lh_hfe_joint">
      <hardwareInterface>hardware_interface/EffortJointInterface</hardwareInterface>
    </joint>
    <actuator name="lh_hfe_motor">
      <hardwareInterface>hardware_interface/EffortJointInterface</hardwareInterface>
      <mechanicalReduction>1</mechanicalReduction>
    </actuator>
  </transmission>
  <!-- Lower leg -->
  <transmission name="lh_kfe_trans">
    <type>transmission_interface/SimpleTransmission</type>
    <joint name="lh_kfe_joint">
      <hardwareInterface>hardware_interface/EffortJointInterface</hardwareInterface>
    </joint>
    <actuator name="lh_kfe_motor">
      <hardwareInterface>hardware_interface/EffortJointInterface</hardwareInterface>
      <mechanicalReduction>1</mechanicalReduction>
    </actuator>
  </transmission>
  <gazebo reference="lh_haa_joint">
    <provideFeedback>true</provideFeedback>
  </gazebo>
  <gazebo reference="lh_kfe_joint">
    <provideFeedback>true</provideFeedback>
  </gazebo>
  <gazebo reference="lh_hfe_joint">
    <provideFeedback>true</provideFeedback>
  </gazebo>
  <gazebo reference="lh_upperleg">
    <kp>1000000.0</kp>
    <kd>100.0</kd>
    <mu1>1.5</mu1>
    <mu2>1.5</mu2>
    <fdir1>1 0 0</fdir1>
    <maxVel>1.0</maxVel>
    <minDepth>0.00</minDepth>
  </gazebo>
  <gazebo reference="lh_lowerleg">
    <kp>1000000.0</kp>
    <kd>100.0</kd>
    <mu1>1.0</mu1>
    <mu2>1.0</mu2>
    <maxVel>1.0</maxVel>
    <maxContacts>1</maxContacts>
    <sensor name="lh_shin_contact_sensor" type="contact">
      <always_on>true</always_on>
      <update_rate>250.0</update_rate>
      <contact>
        <collision>lh_lowerleg_collision</collision>
      </contact>
      <!-- the sensor readings in terms of force torques are expressed in the lowerleg frame
                because gazebo lumps the fake footframe with the real parent link, the normals are in the world frame-->
      <plugin filename="libgazebo_ros_bumper.so" name="lh_shin_bumper">
        <bumperTopicName>/solo_fw/lh_shin_bumper</bumperTopicName>
      </plugin>
    </sensor>
  </gazebo>
  <gazebo reference="lh_foot">
    <kp>1000000.0</kp>
    <kd>100.0</kd>
    <mu1>0.8</mu1>
    <mu2>0.8</mu2>
    <maxVel>1.0</maxVel>
    <maxContacts>1</maxContacts>
    <sensor name="lh_foot_contact_sensor" type="contact">
      <always_on>true</always_on>
      <update_rate>1000.0</update_rate>
      <contact>
        <collision>lh_lowerleg_fixed_joint_lump__lh_foot_collision_1</collision>
      </contact>
      <!-- the sensor readings in terms of force torques are expressed in the lowerleg frame
                                because gazebo lumps the fake footframe with the real parent link, the normals are in the world frame-->
      <plugin filename="libgazebo_ros_bumper.so" name="lh_foot_bumper">
        <bumperTopicName>/solo_fw/lh_foot_bumper</bumperTopicName>
        <!--robotNamespace>solo</robotNamespace-->
        <frameName>lh_foot</frameName>
      </plugin>
    </sensor>
    <material>Gazebo/Black</material>
  </gazebo>
  <!--HAA JOINT: Joint between the trunk and the hip assembly -->
  <joint name="rh_haa_joint" type="revolute">
    <parent link="trunk"/>
    <child link="rh_hip_assembly"/>
    <!-- joints rotates around the x-axis -->
    <axis xyz="1 0 0"/>
    <!-- limit and placement of the joint -->
    <!-- RH_HAA_JOINT -->
    <!-- lower=-140deg, upper=75, velocity=555.5rpm (=5000rpm motor-side) -->
    <limit effort="1.575" lower="-2.44346095" upper="1.30899694" velocity="58.17764173"/>
    <origin rpy="0 0 0" xyz="-0.1946 -0.08750000000000001 0"/>
    <!-- pybullet simulation parameters -->
    <dynamics damping="0.0" friction="0.0"/>
  </joint>
  <!-- HIP ASSEMBLY -->
  <link name="rh_hip_assembly">
    <!-- create a dummy hip_assembly link to join the two joints -->
    <!-- HIP ASSEMBLY VISUAL-->
    <visual>
      <!-- RH HIP ASSEMBLY -->
      <origin rpy="0 0 0" xyz="-0.01950 0 0"/>
      <geometry>
        <mesh filename="package://solo_description/meshes/stl/solo12/solo12_hip_fe_hr.stl"/>
      </geometry>
      <material name="grey">
        <color rgba="0.8 0.8 0.8 1.0"/>
      </material>
    </visual>
    <!-- HIP ASSEMBLY COLLISION-->
    <collision>
      <!-- RH HIP ASSEMBLY -->
      <origin rpy="0 0 0" xyz="-0.01950 0 0"/>
      <geometry>
        <mesh filename="package://solo_description/meshes/stl/solo12/solo12_hip_fe_hr.stl"/>
      </geometry>
      <material name="grey">
        <color rgba="0.8 0.8 0.8 1.0"/>
        xacro
                	
      </material>
    </collision>
    <!-- HIP ASSEMBLY INERTIAL -->
    <inertial>
      <mass value="0.14853845"/>
      <!-- RH HIP ASSEMBLY -->
      <origin rpy="0 0 0" xyz="0.07870700 -0.01 0."/>
      <inertia ixx="0.00003024" ixy="-0.00004671" ixz="0.0" iyy="0.00041193" iyz="0.0" izz="0.00041107"/>
    </inertial>
  </link>
  <!--HFE JOINT-->
  <joint name="rh_hfe_joint" type="revolute">
    <parent link="rh_hip_assembly"/>
    <child link="rh_upperleg"/>
    <!-- joints rotates around the y-axis -->
    <axis xyz="0 1 0"/>
    <!-- RF_HFE_JOINT -->
    <!-- lower=-90deg, upper=225deg, velocity=555.5rpm (=5000rpm motor-side) -->
    <limit effort="1.575" lower="-1.57079633" upper="3.92699082" velocity="58.17764173"/>
    <origin rpy="0 0 0" xyz="0 -0.014 0"/>
    <!-- pybullet simulation parameters -->
    <dynamics damping="0.0" friction="0.0"/>
  </joint>
  <!-- UPPER LEG LINK -->
  <link name="rh_upperleg">
    <!-- Right upper leg inertia -->
    <inertial>
      <origin rpy="0 0 0" xyz="-0.00001377 -0.01935853 -0.07870700"/>
      <mass value="0.14853845"/>
      <inertia ixx="0.00041107" ixy="0.0" ixz="0.0" iyy="0.00041193" iyz="-0.00004671" izz="0.00003024"/>
    </inertial>
    <!-- UPPER LEG LINK VISUAL -->
    <visual>
      <origin rpy="0 0 0" xyz="0 0 0"/>
      <geometry>
        <mesh filename="package://solo_description/meshes/stl/with_foot/solo_upper_leg_right_side.stl"/>
      </geometry>
      <material name="grey">
        <color rgba="0.8 0.8 0.8 1.0"/>
      </material>
    </visual>
    <!-- UPPER LEG LINK COLLISION -->
    <collision>
      <origin rpy="0 0 0" xyz="0 0 0"/>
      <geometry>
        <mesh filename="package://solo_description/meshes/stl/with_foot/solo_upper_leg_right_side.stl"/>
      </geometry>
      <material name="grey">
        <color rgba="0.8 0.8 0.8 1.0"/>
      </material>
    </collision>
    <!-- Bullet specific paramters -->
    <contact>
      <lateral_friction value="1.0"/>
      <restitution value="0.5"/>
    </contact>
  </link>
  <!-- END UPPER LEG LINK -->
  <!-- KFE JOINT: Joint between the upper leg and the lower leg -->
  <joint name="rh_kfe_joint" type="revolute">
    <parent link="rh_upperleg"/>
    <child link="rh_lowerleg"/>
    <!-- joints rotates around the y-axis -->
    <axis xyz="0 1 0"/>
    <!-- RH_KFE JOINT -->
    <!-- lower=-370deg, upper=370deg, velocity=555.5rpm (=5000rpm motor-side) -->
    <limit effort="1.575" lower="-6.45771823" upper="6.45771823" velocity="58.17764173"/>
    <origin rpy="0 0 0" xyz="0 -0.037450000000000004 -0.16"/>
    <!-- pybullet simulation parameters -->
    <dynamics damping="0.0" friction="0.0"/>
  </joint>
  <!-- LOWERLEG -->
  <link name="rh_lowerleg">
    <!-- Right lower leg inertia -->
    <inertial>
      <origin rpy="0 0 0" xyz="0.0 0.00787644 -0.08928215"/>
      <mass value="0.03070001"/>
      <inertia ixx="0.00012024" ixy="0.0" ixz="0.0" iyy="0.00012029" iyz="-0.00000305" izz="0.00000216"/>
    </inertial>
    <!-- LOWER LEG LINK VISUAL -->
    <visual>
      <origin rpy="0 0 0" xyz="0 0 0"/>
      <geometry>
        <mesh filename="package://solo_description/meshes/stl/with_foot/solo_lower_leg_right_side.stl"/>
      </geometry>
      <material name="grey">
        <color rgba="0.8 0.8 0.8 1.0"/>
      </material>
    </visual>
    <!-- LOWER LEG LINK COLLISION -->
    <collision>
      <origin rpy="0 0 0" xyz="0 0 0"/>
      <geometry>
        <mesh filename="package://solo_description/meshes/stl/with_foot/solo_lower_leg_right_side.stl"/>
      </geometry>
      <material name="grey">
        <color rgba="0.8 0.8 0.8 1.0"/>
      </material>
    </collision>
    <!-- Bullet specific paramters -->
    <contact>
      <lateral_friction value="1.0"/>
      <restitution value="0.5"/>
    </contact>
  </link>
  <!-- END LOWER LEG LINK -->
  <!-- ANKLE: (Fixed) joint between the lower leg and the foot -->
  <joint name="rh_ankle" type="fixed">
    <parent link="rh_lowerleg"/>
    <child link="rh_foot"/>
    <origin rpy="0 0 0" xyz="0 -0.008 -0.16"/>
    <!-- pybullet simulation parameters -->
    <dynamics damping="0.0" friction="0.0"/>
  </joint>
  <!-- FOOT -->
  <link name="rh_foot">
    <!-- FOOT INERTIAL -->
    <!-- This link is symmetrical left or right -->
    <inertial>
      <origin rpy="0 0 0" xyz="0 0 0.00035767"/>
      <mass value="0.00693606"/>
      <inertia ixx="0.00000057" ixy="0.0" ixz="0.0" iyy="0.00000084" iyz="0.0" izz="0.00000053"/>
    </inertial>
    <!-- FOOT VISUAL -->
    <visual>
      <origin rpy="0 0 0" xyz="0 0 0"/>
      <geometry>
        <mesh filename="package://solo_description/meshes/stl/with_foot/solo_foot.stl"/>
      </geometry>
      <material name="grey">
        <color rgba="0.8 0.8 0.8 1.0"/>
      </material>
    </visual>
    <!-- FOOT COLLISION -->
    <collision>
      <origin rpy="0 0 0" xyz="0 0 0"/>
      <geometry>
        <mesh filename="package://solo_description/meshes/stl/with_foot/solo_foot.stl"/>
        <!-- sphere radius="0.01"/-->
      </geometry>
      <material name="grey">
        <color rgba="0.8 0.8 0.8 1.0"/>
      </material>
    </collision>
    <!-- Bullet specific paramters -->
    <contact>
      <lateral_friction value="1.0"/>
      <restitution value="0.5"/>
    </contact>
  </link>
  <!-- END FOOT LINK -->
  <!-- Hip assembly -->
  <transmission name="rh_haa_trans">
    <type>transmission_interface/SimpleTransmission</type>
    <joint name="rh_haa_joint">
      <hardwareInterface>hardware_interface/EffortJointInterface</hardwareInterface>
    </joint>
    <actuator name="rh_haa_motor">
      <hardwareInterface>hardware_interface/EffortJointInterface</hardwareInterface>
      <mechanicalReduction>1</mechanicalReduction>
    </actuator>
  </transmission>
  <!-- Upper leg -->
  <transmission name="rh_hfe_trans">
    <type>transmission_interface/SimpleTransmission</type>
    <joint name="rh_hfe_joint">
      <hardwareInterface>hardware_interface/EffortJointInterface</hardwareInterface>
    </joint>
    <actuator name="rh_hfe_motor">
      <hardwareInterface>hardware_interface/EffortJointInterface</hardwareInterface>
      <mechanicalReduction>1</mechanicalReduction>
    </actuator>
  </transmission>
  <!-- Lower leg -->
  <transmission name="rh_kfe_trans">
    <type>transmission_interface/SimpleTransmission</type>
    <joint name="rh_kfe_joint">
      <hardwareInterface>hardware_interface/EffortJointInterface</hardwareInterface>
    </joint>
    <actuator name="rh_kfe_motor">
      <hardwareInterface>hardware_interface/EffortJointInterface</hardwareInterface>
      <mechanicalReduction>1</mechanicalReduction>
    </actuator>
  </transmission>
  <gazebo reference="rh_haa_joint">
    <provideFeedback>true</provideFeedback>
  </gazebo>
  <gazebo reference="rh_kfe_joint">
    <provideFeedback>true</provideFeedback>
  </gazebo>
  <gazebo reference="rh_hfe_joint">
    <provideFeedback>true</provideFeedback>
  </gazebo>
  <gazebo reference="rh_upperleg">
    <kp>1000000.0</kp>
    <kd>100.0</kd>
    <mu1>1.5</mu1>
    <mu2>1.5</mu2>
    <fdir1>1 0 0</fdir1>
    <maxVel>1.0</maxVel>
    <minDepth>0.00</minDepth>
  </gazebo>
  <gazebo reference="rh_lowerleg">
    <kp>1000000.0</kp>
    <kd>100.0</kd>
    <mu1>1.0</mu1>
    <mu2>1.0</mu2>
    <maxVel>1.0</maxVel>
    <maxContacts>1</maxContacts>
    <sensor name="rh_shin_contact_sensor" type="contact">
      <always_on>true</always_on>
      <update_rate>250.0</update_rate>
      <contact>
        <collision>rh_lowerleg_collision</collision>
      </contact>
      <!-- the sensor readings in terms of force torques are expressed in the lowerleg frame
                because gazebo lumps the fake footframe with the real parent link, the normals are in the world frame-->
      <plugin filename="libgazebo_ros_bumper.so" name="rh_shin_bumper">
        <bumperTopicName>/solo_fw/rh_shin_bumper</bumperTopicName>
      </plugin>
    </sensor>
  </gazebo>
  <gazebo reference="rh_foot">
    <kp>1000000.0</kp>
    <kd>100.0</kd>
    <mu1>0.8</mu1>
    <mu2>0.8</mu2>
    <maxVel>1.0</maxVel>
    <maxContacts>1</maxContacts>
    <sensor name="rh_foot_contact_sensor" type="contact">
      <always_on>true</always_on>
      <update_rate>1000.0</update_rate>
      <contact>
        <collision>rh_lowerleg_fixed_joint_lump__rh_foot_collision_1</collision>
      </contact>
      <!-- the sensor readings in terms of force torques are expressed in the lowerleg frame
                                because gazebo lumps the fake footframe with the real parent link, the normals are in the world frame-->
      <plugin filename="libgazebo_ros_bumper.so" name="rh_foot_bumper">
        <bumperTopicName>/solo_fw/rh_foot_bumper</bumperTopicName>
        <!--robotNamespace>solo</robotNamespace-->
        <frameName>rh_foot</frameName>
      </plugin>
    </sensor>
    <material>Gazebo/Black</material>
  </gazebo>
  <joint name="z_left_wheel_joint" type="revolute">
    <parent link="trunk"/>
    <child link="left_wheel"/>
    <origin rpy="-1.5707963267948966 0 -0.0" xyz="0.0 0.067 0.066"/>
    <axis xyz="0 0 1"/>
    <dynamics damping="0.0" friction="0.0"/>
    <limit effort="0.225" lower="-1e06" upper="1e06" velocity="523"/>
    <!--limit effort="0.675" lower="-1e06" upper="1e06" velocity="4000"/-->
  </joint>
  <link name="left_wheel">
    <inertial>
      <mass value="0.1"/>
      <inertia ixx="3.7e-05" ixy="0" ixz="0" iyy="3.7e-05" iyz="0" izz="6.8e-05"/>
    </inertial>
    <visual>
      <origin rpy="0 0 0" xyz="0 0 0.0"/>
      <geometry>
        <mesh filename="package://solo_description/meshes/stl/flywheel/flywheel.stl" scale="0.001 0.001 0.001"/>
        <!--the measure in the stl files are expressed in mm-->
      </geometry>
    </visual>
    <collision>
      <origin rpy="0 0 0" xyz="0 0 0.0"/>
      <geometry>
        <mesh filename="package://solo_description/meshes/stl/flywheel/flywheel.stl" scale="0.001 0.001 0.001"/>
      </geometry>
    </collision>
  </link>
  <joint name="z_right_wheel_joint" type="revolute">
    <parent link="trunk"/>
    <child link="right_wheel"/>
    <origin rpy="1.5707963267948966 0 0.0" xyz="0.0 -0.067 0.066"/>
    <axis xyz="0 0 1"/>
    <dynamics damping="0.0" friction="0.0"/>
    <limit effort="0.225" lower="-1e06" upper="1e06" velocity="523"/>
    <!--limit effort="0.675" lower="-1e06" upper="1e06" velocity="4000"/-->
  </joint>
  <link name="right_wheel">
    <inertial>
      <mass value="0.1"/>
      <inertia ixx="3.7e-05" ixy="0" ixz="0" iyy="3.7e-05" iyz="0" izz="6.8e-05"/>
    </inertial>
    <visual>
      <origin rpy="0 0 0" xyz="0 0 0.0"/>
      <geometry>
        <mesh filename="package://solo_description/meshes/stl/flywheel/flywheel.stl" scale="0.001 0.001 0.001"/>
      </geometry>
    </visual>
    <collision>
      <origin rpy="0 0 0" xyz="0 0 0.0"/>
      <geometry>
        <mesh filename="package://solo_description/meshes/stl/flywheel/flywheel.stl" scale="0.001 0.001 0.001"/>
      </geometry>
    </collision>
  </link>
  <transmission name="z_right_wheel_trans">
    <type>transmission_interface/SimpleTransmission</type>
    <joint name="z_right_wheel_joint">
      <hardwareInterface>hardware_interface/EffortJointInterface</hardwareInterface>
    </joint>
    <actuator name="z_right_wheel_motor">
      <hardwareInterface>hardware_interface/EffortJointInterface</hardwareInterface>
      <mechanicalReduction>1</mechanicalReduction>
    </actuator>
  </transmission>
  <transmission name="z_left_wheel_trans">
    <type>transmission_interface/SimpleTransmission</type>
    <joint name="z_left_wheel_joint">
      <hardwareInterface>hardware_interface/EffortJointInterface</hardwareInterface>
    </joint>
    <actuator name="z_left_wheel_motor">
      <hardwareInterface>hardware_interface/EffortJointInterface</hardwareInterface>
      <mechanicalReduction>1</mechanicalReduction>
    </actuator>
  </transmission>
  <gazebo reference="left_wheel">
    <material>Gazebo/Red</material>
    <!-- kp and kd for rubber -->
    <kp>1000000.0</kp>
    <kd>100.0</kd>
    <mu1>1.0</mu1>
    <mu2>1.0</mu2>
    <fdir1>1 0 0</fdir1>
    <maxVel>1.0</maxVel>
    <minDepth>0.00</minDepth>
  </gazebo>
  <gazebo reference="right_wheel">
    <material>Gazebo/Grey</material>
    <!-- kp and kd for rubber -->
    <kp>1000000.0</kp>
    <kd>100.0</kd>
    <mu1>1.0</mu1>
    <mu2>1.0</mu2>
    <fdir1>1 0 0</fdir1>
    <maxVel>1.0</maxVel>
    <minDepth>0.00</minDepth>
  </gazebo>
</robot>
