<?xml version="1.0" ?>

<robot name="rmr" xmlns:xacro="http://www.ros.org/wiki/xacro">

    <link name="world"/>
    <joint name="world_joint" type="fixed">
        <parent link="world"/>
        <child link="base_link"/>
        <origin rpy="0.0 0.0 0.0" xyz="0.0 0.0 0.0"/>
    </joint>

    <link name = "base_link">
        <visual>
            <geometry>
                <mesh filename="package://example-robot-data/robots/ur_description/meshes/ur5/collision/base.stl"/>
            </geometry>
        </visual>
        <collision>
            <geometry>
                <mesh filename="package://example-robot-data/robots/ur_description/meshes/ur5/collision/base.stl"/>
            </geometry>
        </collision>
        <inertial>
            <mass value="4.0"/>
            <origin rpy="0 0 0" xyz="0.0 0.0 0.0"/>
            <inertia ixx="0.00443333156" ixy="0.0" ixz="0.0" iyy="0.00443333156" iyz="0.0" izz="0.0072"/>
        </inertial>
    </link>

    <joint name="shoulder_pan_joint" type="revolute">
        <parent link="base_link"/>
        <child link="shoulder_link"/>
        <origin rpy="0.0 0.0 0.0" xyz="0.0 0.0 0.089159"/>
        <axis xyz="0 0 1"/>
        <limit effort="150.0" lower="-3.14159265" upper="3.14159265" velocity="3.15"/>
        <dynamics damping="0.0" friction="0.0"/>
    </joint>


    <link name="shoulder_link">
        <visual>
            <geometry>
                <mesh filename="package://example-robot-data/robots/ur_description/meshes/ur5/collision/shoulder.stl"/>
            </geometry>
        </visual>
        <collision>
            <!-- <origin rpy="0 0 0" xyz="0 0 0.2" /> -->
            <geometry>
                <mesh filename="package://example-robot-data/robots/ur_description/meshes/ur5/collision/shoulder.stl"/>
            </geometry>
        </collision>
        <inertial>
            <mass value="3.7"/>
            <origin rpy="0 0 0" xyz="0 0 0.2" />
            <inertia ixx="0.010267495893" ixy="0.0" ixz="0.0" iyy="0.010267495893" iyz="0.0" izz="0.00666"/>
        </inertial>
    </link>


  <transmission name="shoulder_pan_trans">
    <type>transmission_interface/SimpleTransmission</type>
    <joint name="shoulder_pan_joint">
      <hardwareInterface>PositionJointInterface</hardwareInterface>
    </joint>
    <actuator name="shoulder_pan_motor">
      <mechanicalReduction>1</mechanicalReduction>
    </actuator>
  </transmission>


</robot>
